Workbook

Sheet Anleitung
A1: Anleitung zur Nutzung dieser Excel-Datei
A3: Schritt 1: Daten zur Übung eintragen
B4: 1) Wählen Sie das Blatt "Uebung".
B5: 2) Tragen Sie dort die Veranstaltungsinformationen in die gelb hinterlegten Felder ein.
A7: Schritt 2: Teilnehmende eintragen
B8: 1) Exportieren Sie die Teilnehmer-Liste aus myStudy und öffnen Sie die Datei.
B9: 2) Klicken Sie in die Liste mit den Namen, wählen den gesamten Inhalt der Tabelle aus und kopieren Sie sie.
B10: 3) Wechseln Sie in diese Datei und wählen Sie das Blatt "TN-Liste".
B11: 4) Klicken Sie in die oberste linke Zelle, also die Zelle A1 (gelb hinterlegt).
B12: 5) Setzen Sie den kopierten Inhalt ein.
B13: Alle Informationen zu den Teilnehmenden sind nun zu sehen. Die Namen der Studierenden werden in die anderen Blätter automatisch übernommen, so dass Sie die Namen dort nicht noch einmal eintragen müssen.
B14: Sie können diese Liste ergänzen, bpsw. um spätere Anmeldungen zu berücksichtigen.
B15: Bitte beachten Sie! Die Liste wird in der eingetragenen Form übernommen. Ergänzungen der Liste sind auch jederzeit möglich.
B17: Hinweis:
B18: In das Blatt "Bewertungen" werden die Daten aus den Spalten B (Vorname) und C (Nachname) ab Zeile 2 übernommen. Wenn Sie die Daten manuell eintragen, beginnen Sie in der Zelle B2, da die Tabelle in myStudy eine Kopfzeile hat.
A20: Schritt 3: Bewertungen eintragen
B21: 1) Wechseln Sie auf das Blatt "Bewertungen". Die Namen der Studierenden sind automatisch eingetragen
B22: 2) Tragen Sie für die Punkte für die Artefakte ein. Bitte vergeben Sie nur volle Punkte.
B23: 3) Die Punkte werden automatisch je Studierende in Zeile 32 ausgegeben.
A25: Schritt 4: Bewertungen an die Studierenden übermitteln
B26: In der Arbeitsmappe gibt es für jede*n Teilnehmer*in ein eigenes Blatt. Angelegt sind 40 Studierende: Stud1 bis Stud40.
B27: Die Reihenfolge ist dieselbe wie die TN-Liste. In dieses werden die Bewertungskriterien sowie die Punktwerte aus dem Blatt "Bewertungen" automatisch übernommen.
B28: Um den Studierenden ihre individuellen Punkte zuzusenden,
B29: 1) wechseln Sie auf das entsprechende Blatt: Stud1 bis Stud2
B30: 2) Erzeugen Sie von dem Blatt ein pdf. Hierfür wählen Sie "Speichern unter…", stellen Sie das Einblendmenü "Dateiformat" auf "pdf" und klicken Sie speichern.
B31: Sie können das pdf den Studierenden einzeln per E-Mail zukommen lassen.
A33: Schritt 5: Einreichung der Bewertungen an das Prüfungsamt
B34: Sie können diese Excel-Datei vollständig an das Prüfungsamt übermitteln
A38: Bewertungen: Seitenansicht splitten
B39: Damit die Bewertungskriterien permanent sichtbar bleiben, kann die Ansicht gesplittet werden. Dies ist in dieser Version bereits getan.
B40: Im horizontalen Scrollbalken befindet sich eine kleine doppelte Linie (s. Abb.), die man anklicken und ziehen kann.
B42: #VALUE!

Sheet Uebung
A1: Bitte tragen Sie in dieses Blatt Ihren Namen, den Titel der Übung und die Veranstaltungsnummer ein:
A3: Dozent/in
A4: Veranstaltungstitel
A5: Veranstaltungsnummer

Sheet TN-Liste

Sheet Bewertungen
A1: Sie können je Kritierum bis zu 5 Punkten vergeben. Bitte vergeben Sie nur ganze Punkte. | AS1: 10
B2: 4–5= vollständig erkennbar
B3: 2–3 = weitgehend erkennbar
B4: 1 = erste Ansätze erkennbar
B5: 0 = nicht erkennbar
D6: Namen der Teilnehmenden (werden automatisch aus dem Blatt TN-Liste übernommen)
D7: ='TN-Liste'!$C$2 -> 0 | E7: ='TN-Liste'!$C$3 -> 0 | F7: ='TN-Liste'!$C$4 -> 0 | G7: ='TN-Liste'!$C$5 -> 0 | H7: ='TN-Liste'!$C$6 -> 0 | I7: ='TN-Liste'!$C$7 -> 0 | J7: ='TN-Liste'!$C$8 -> 0 | K7: ='TN-Liste'!$C$9 -> 0 | L7: ='TN-Liste'!$C$10 -> 0 | M7: ='TN-Liste'!$C$11 -> 0 | N7: ='TN-Liste'!$C$12 -> 0 | O7: ='TN-Liste'!$C$13 -> 0 | P7: ='TN-Liste'!$C$14 -> 0 | Q7: ='TN-Liste'!$C$15 -> 0 | R7: ='TN-Liste'!$C$16 -> 0 | S7: ='TN-Liste'!$C$17 -> 0 | T7: ='TN-Liste'!$C$18 -> 0 | U7: ='TN-Liste'!$C$19 -> 0 | V7: ='TN-Liste'!$C$20 -> 0 | W7: ='TN-Liste'!$C$21 -> 0 | X7: ='TN-Liste'!$C$22 -> 0 | Y7: ='TN-Liste'!$C$23 -> 0 | Z7: ='TN-Liste'!$C$24 -> 0 | AA7: ='TN-Liste'!$C$25 -> 0 | AB7: ='TN-Liste'!$C$26 -> 0 | AC7: ='TN-Liste'!$C$27 -> 0 | AD7: ='TN-Liste'!$C$28 -> 0 | AE7: ='TN-Liste'!$C$29 -> 0 | AF7: ='TN-Liste'!$C$30 -> 0 | AG7: ='TN-Liste'!$C$31 -> 0 | AH7: ='TN-Liste'!$C$32 -> 0 | AI7: ='TN-Liste'!$C$33 -> 0 | AJ7: ='TN-Liste'!$C$34 -> 0 | AK7: ='TN-Liste'!$C$35 -> 0 | AL7: ='TN-Liste'!$C$36 -> 0 | AM7: ='TN-Liste'!$C$37 -> 0 | AN7: ='TN-Liste'!$C$38 -> 0 | AO7: ='TN-Liste'!$C$39 -> 0 | AP7: ='TN-Liste'!$C$40 -> 0 | AQ7: ='TN-Liste'!$C$41 -> 0
D8: ='TN-Liste'!$B$2 -> 0 | E8: ='TN-Liste'!$B$3 -> 0 | F8: ='TN-Liste'!$B$4 -> 0 | G8: ='TN-Liste'!$B$5 -> 0 | H8: ='TN-Liste'!$B$6 -> 0 | I8: ='TN-Liste'!$B$7 -> 0 | J8: ='TN-Liste'!$B$8 -> 0 | K8: ='TN-Liste'!$B$9 -> 0 | L8: ='TN-Liste'!$B$10 -> 0 | M8: ='TN-Liste'!$B$11 -> 0 | N8: ='TN-Liste'!$B$12 -> 0 | O8: ='TN-Liste'!$B$13 -> 0 | P8: ='TN-Liste'!$B$14 -> 0 | Q8: ='TN-Liste'!$B$15 -> 0 | R8: ='TN-Liste'!$B$16 -> 0 | S8: ='TN-Liste'!$B$17 -> 0 | T8: ='TN-Liste'!$B$18 -> 0 | U8: ='TN-Liste'!$B$19 -> 0 | V8: ='TN-Liste'!$B$20 -> 0 | W8: ='TN-Liste'!$B$21 -> 0 | X8: ='TN-Liste'!$B$22 -> 0 | Y8: ='TN-Liste'!$B$23 -> 0 | Z8: ='TN-Liste'!$B$24 -> 0 | AA8: ='TN-Liste'!$B$25 -> 0 | AB8: ='TN-Liste'!$B$26 -> 0 | AC8: ='TN-Liste'!$B$27 -> 0 | AD8: ='TN-Liste'!$B$28 -> 0 | AE8: ='TN-Liste'!$B$29 -> 0 | AF8: ='TN-Liste'!$B$30 -> 0 | AG8: ='TN-Liste'!$B$31 -> 0 | AH8: ='TN-Liste'!$B$32 -> 0 | AI8: ='TN-Liste'!$B$33 -> 0 | AJ8: ='TN-Liste'!$B$34 -> 0 | AK8: ='TN-Liste'!$B$35 -> 0 | AL8: ='TN-Liste'!$B$36 -> 0 | AM8: ='TN-Liste'!$B$37 -> 0 | AN8: ='TN-Liste'!$B$38 -> 0 | AO8: ='TN-Liste'!$B$39 -> 0 | AP8: ='TN-Liste'!$B$40 -> 0 | AQ8: ='TN-Liste'!$B$41 -> 0
A9: Artefakt | B9: Kriterien
A11: Fragestellung (Artefakt 1a) | B11: Es liegt eine präzise formulierte Fragestellung vor, die sich auf ein konkretes Thema bezieht.
A12: Reflexionen (Artefakt 1b, 2d, 3 und 4) | B12: Es wird deutlich, dass eine bewusste Beschäftigung mit dem jeweiligen Thema der einzelnen Aufgabe stattgefunden hat.
B13: Die Ausgangslage der jeweiligen Reflexion wird beschrieben.
B14: Die beschriebene Ausgangslage wird analysiert.
B15: Es werden Verbindungen zwischen Lernerfahrungen hergestellt, z. B. zwischen aktuellen und früheren oder zwischen verschiedenen Lernsituationen etc.
B16: Vorhandene Vorannahmen, Vorurteile und Stereotype etc. werden hinterfragt.
B17: Es wird deutlich, dass der*die Schreibende zu neuen Erkenntnissen gelangt ist.
B18: Aus diesen neuen Erkenntnissen werden Implikationen für das zukünftige Denken und Handeln abgeleitet.
A19: Response Paper (Artefakt 2a-c) | B19: Arbeitet die wesentlichen Thesen des Artikels präzise heraus.
B20: Belegt die herausgearbeiteten Thesen mit Verweisen auf den Text.
B21: Ordnet die herausgearbeiteten Thesen anhand weiterer Literatur ein.
B22: Bezieht kontextuelle Informationen zum Text (z. B. Lebensdaten des/der Autor*in, Denkschule, geschichtliche Einordnung, Zielpublikum) in die Einordnung ein.
B23: Positioniert sich gegenüber der herausgearbeiteten These.
B24: Begründet diese Stellung mit einer nachvollziehbaren und schlüssigen Argumentation.
B25: Der sprachliche Ausdruck ist einem wissenschaftlichen Text angemessen.
A26: gesamtes Portfolio | B26: Die Texte sind für Lesende verständlich und nachvollziehbar geschrieben.
B27: Intertextualität ist im Text transparent und nachvollziehbar formuliert. D. h. es ist durchgängig klar/eindeutig zuzuordnen, wer „spricht“, d.h. wessen Position/Meinung/ Beitrag referiert wird bzw. ob der/die Autor*in selbst „spricht“.
B28: Die verwendete Literatur wird nachvollziehbar und einheitlich zitiert.
B29: Die Einteilung in Absätze unterstützt das Textverständnis.
B30: Über dieses Kriterium wird bewertet, wie gut das gesamte Portfolio den Regeln der Rechtschreibung, Zeichensetzung und Grammatik entspricht. 5 = fehlerfrei 4 = wenige Flüchtigkeitsfehler 3 = Text enthält auffällige Fehler; das Textverständnis ist noch nicht eingeschränkt. 2 = Text enthält viele Fehler, so dass das Textverständnis eingeschränkt ist. 1 = Text enthält viele Fehler, so dass das Textverständnis erheblich eingeschränkt ist. 0 = enthält so viele Fehler, dass ein Textverständnis nicht mehr gegeben ist.
B32: Gesamtpunktzahl | D32: =SUM(D11:D30) -> 0 | E32: =SUM(E11:E30) -> 0 | F32: =SUM(F11:F30) -> 0 | G32: =SUM(G11:G30) -> 0 | H32: =SUM(H11:H30) -> 0 | I32: =SUM(I11:I30) -> 0 | J32: =SUM(J11:J30) -> 0 | K32: =SUM(K11:K30) -> 0 | ... AQ32: =SUM(AQ11:AQ30) -> 0

Sheet Stud1
A1: Übung | B1: =Uebung!B3 -> 0
A2: Leitung | B2: =Uebung!B4 -> 0
A3: Nummer | B3: =Uebung!B5 -> 0
A5: Nachname | B5: =OFFSET(Bewertungen!$D$7,Bewertungen!$AS$10,0) -> 0
A6: Vorname | B6: =OFFSET(Bewertungen!$D$8,Bewertungen!$AS$10,0) -> 0
A8: Sie können max. 100 Punkte erreichen. Je Kriterium max. 5 Punkte.
A9: Punktwerte bedeuten: | B9: 4–5= vollständig erkennbar
B10: 2–3 = weitgehend erkennbar
B11: 1 = erste Ansätze erkennbar
B12: 0 = nicht erkennbar
B13: Ihre Gesamtpunktzahl: | C13: =OFFSET(Bewertungen!$D$32,Bewertungen!$AS$10,0) -> 0
A15: Artefakt | B15: Kriterien | C15: Punkte
A17: Fragestellung (Artefakt 1a) | B17: Es liegt eine präzise formulierte Fragestellung vor, die sich auf ein konkretes Thema bezieht. | C17: =OFFSET(Bewertungen!D11,Bewertungen!$AS$10,0) -> 0
A18: Reflexionen (Artefakt 1b, 2d, 3 und 4) | B18: Es wird deutlich, dass eine bewusste Beschäftigung mit dem Thema stattgefunden hat. | C18: =OFFSET(Bewertungen!D12,Bewertungen!$AS$10,0) -> 0
B19: Die Ausgangslage der Reflexion wird beschrieben. | C19: =OFFSET(Bewertungen!D13,Bewertungen!$AS$10,0) -> 0
B20: Die beschriebene Ausgangslage wird analysiert. | C20: =OFFSET(Bewertungen!D14,Bewertungen!$AS$10,0) -> 0
B21: Es werden Verbindungen zwischen Lernerfahrungen hergestellt, z. B. zwischen aktuellen und früheren oder zwischen verschiedenen Lernsituationen etc. | C21: =OFFSET(Bewertungen!D15,Bewertungen!$AS$10,0) -> 0
B22: Vorhandene Vorannahmen, Vorurteile und Stereotype etc. werden hinterfragt. | C22: =OFFSET(Bewertungen!D16,Bewertungen!$AS$10,0) -> 0
B23: Es wird deutlich, dass der*die Schreibende zu neuen Erkenntnissen gelangt ist. | C23: =OFFSET(Bewertungen!D17,Bewertungen!$AS$10,0) -> 0
B24: Aus diesen neuen Erkenntnissen werden Implikationen für das zukünftige Denken und Handeln abgeleitet. | C24: =OFFSET(Bewertungen!D18,Bewertungen!$AS$10,0) -> 0
A25: Response Paper (Artefakt 2a-c) | B25: Arbeitet die wesentlichen Thesen des Artikels präzise heraus. | C25: =OFFSET(Bewertungen!D19,Bewertungen!$AS$10,0) -> 0
B26: Belegt die herausgearbeiteten Thesen mit Verweisen auf den Text | C26: =OFFSET(Bewertungen!D20,Bewertungen!$AS$10,0) -> 0
B27: Ordnet die herausgearbeiteten Thesen anhand weiterer Literatur ein. | C27: =OFFSET(Bewertungen!D21,Bewertungen!$AS$10,0) -> 0
B28: Bezieht kontextuelle Informationen zum Text (z. B. Lebensdaten des/der Autor*in, Denkschule, geschichtliche Einordnung, Zielpublikum) in die Einordnung ein. | C28: =OFFSET(Bewertungen!D22,Bewertungen!$AS$10,0) -> 0
B29: Positioniert sich gegenüber der herausgearbeiteten These. | C29: =OFFSET(Bewertungen!D23,Bewertungen!$AS$10,0) -> 0
B30: Begründet diese Stellung mit einer nachvollziehbaren und schlüssigen Argumentation. | C30: =OFFSET(Bewertungen!D24,Bewertungen!$AS$10,0) -> 0
B31: Der sprachliche Ausdruck ist einem wissenschaftlichen Text angemessen. | C31: =OFFSET(Bewertungen!D25,Bewertungen!$AS$10,0) -> 0
A32: gesamtes Portfolio | B32: Die Texte sind für Lesende verständlich und nachvollziehbar geschrieben. | C32: =OFFSET(Bewertungen!D26,Bewertungen!$AS$10,0) -> 0
B33: Intertextualität ist im Text transparent und nachvollziehbar formuliert. D. h. es ist durchgängig klar/eindeutig zuzuordnen, wer „spricht“, d.h. wessen Position/Meinung/ Beitrag referiert wird bzw. ob der/die Autor*in selbst „spricht“. | C33: =OFFSET(Bewertungen!D27,Bewertungen!$AS$10,0) -> 0
B34: Die verwendete Literatur wird nachvollziehbar und einheitlich zitiert. | C34: =OFFSET(Bewertungen!D28,Bewertungen!$AS$10,0) -> 0
B35: Die Einteilung in Absätze unter stützt das Textverständnis. | C35: =OFFSET(Bewertungen!D29,Bewertungen!$AS$10,0) -> 0
B36: Die Texte sind weitestgehend fehlerfrei in Bezug auf Rechtschreibung, Zeichensetzung und Grammatik. | C36: =OFFSET(Bewertungen!D30,Bewertungen!$AS$10,0) -> 0

Sheet Stud2
A1: Übung | B1: =Uebung!B3 -> 0
A2: Leitung | B2: =Uebung!B4 -> 0
A3: Nummer | B3: =Uebung!B5 -> 0
A5: Nachname | B5: =OFFSET(Bewertungen!$E$7,Bewertungen!$AS$10,0) -> 0
A6: Vorname | B6: =OFFSET(Bewertungen!$E$8,Bewertungen!$AS$10,0) -> 0
A8: Sie können max. 100 Punkte erreichen. Je Kriterium max. 5 Punkte.
A9: Punktwerte bedeuten: | B9: 4–5= vollständig erkennbar
B10: 2–3 = weitgehend erkennbar
B11: 1 = erste Ansätze erkennbar
B12: 0 = nicht erkennbar
B13: Ihre Gesamtpunktzahl: | C13: =OFFSET(Bewertungen!$E$32,Bewertungen!$AS$10,0) -> 0
A15: Artefakt | B15: Kriterien | C15: Punkte
A17: Fragestellung (Artefakt 1a) | B17: Es liegt eine präzise formulierte Fragestellung vor, die sich auf ein konkretes Thema bezieht. | C17: =OFFSET(Bewertungen!E11,Bewertungen!$AS$10,0) -> 0
A18: Reflexionen (Artefakt 1b, 2d, 3 und 4) | B18: Es wird deutlich, dass eine bewusste Beschäftigung mit dem Thema stattgefunden hat. | C18: =OFFSET(Bewertungen!E12,Bewertungen!$AS$10,0) -> 0
B19: Die Ausgangslage der Reflexion wird beschrieben. | C19: =OFFSET(Bewertungen!E13,Bewertungen!$AS$10,0) -> 0
B20: Die beschriebene Ausgangslage wird analysiert. | C20: =OFFSET(Bewertungen!E14,Bewertungen!$AS$10,0) -> 0
B21: Es werden Verbindungen zwischen Lernerfahrungen hergestellt, z. B. zwischen aktuellen und früheren oder zwischen verschiedenen Lernsituationen etc. | C21: =OFFSET(Bewertungen!E15,Bewertungen!$AS$10,0) -> 0
B22: Vorhandene Vorannahmen, Vorurteile und Stereotype etc. werden hinterfragt. | C22: =OFFSET(Bewertungen!E16,Bewertungen!$AS$10,0) -> 0
B23: Es wird deutlich, dass der*die Schreibende zu neuen Erkenntnissen gelangt ist. | C23: =OFFSET(Bewertungen!E17,Bewertungen!$AS$10,0) -> 0
B24: Aus diesen neuen Erkenntnissen werden Implikationen für das zukünftige Denken und Handeln abgeleitet. | C24: =OFFSET(Bewertungen!E18,Bewertungen!$AS$10,0) -> 0
A25: Response Paper (Artefakt 2a-c) | B25: Arbeitet die wesentlichen Thesen des Artikels präzise heraus. | C25: =OFFSET(Bewertungen!E19,Bewertungen!$AS$10,0) -> 0
B26: Belegt die herausgearbeiteten Thesen mit Verweisen auf den Text | C26: =OFFSET(Bewertungen!E20,Bewertungen!$AS$10,0) -> 0
B27: Ordnet die herausgearbeiteten Thesen anhand weiterer Literatur ein. | C27: =OFFSET(Bewertungen!E21,Bewertungen!$AS$10,0) -> 0
B28: Bezieht kontextuelle Informationen zum Text (z. B. Lebensdaten des/der Autor*in, Denkschule, geschichtliche Einordnung, Zielpublikum) in die Einordnung ein. | C28: =OFFSET(Bewertungen!E22,Bewertungen!$AS$10,0) -> 0
B29: Positioniert sich gegenüber der herausgearbeiteten These. | C29: =OFFSET(Bewertungen!E23,Bewertungen!$AS$10,0) -> 0
B30: Begründet diese Stellung mit einer nachvollziehbaren und schlüssigen Argumentation. | C30: =OFFSET(Bewertungen!E24,Bewertungen!$AS$10,0) -> 0
B31: Der sprachliche Ausdruck ist einem wissenschaftlichen Text angemessen. | C31: =OFFSET(Bewertungen!E25,Bewertungen!$AS$10,0) -> 0
A32: gesamtes Portfolio | B32: Die Texte sind für Lesende verständlich und nachvollziehbar geschrieben. | C32: =OFFSET(Bewertungen!E26,Bewertungen!$AS$10,0) -> 0
B33: Intertextualität ist im Text transparent und nachvollziehbar formuliert. D. h. es ist durchgängig klar/eindeutig zuzuordnen, wer „spricht“, d.h. wessen Position/Meinung/ Beitrag referiert wird bzw. ob der/die Autor*in selbst „spricht“. | C33: =OFFSET(Bewertungen!E27,Bewertungen!$AS$10,0) -> 0
B34: Die verwendete Literatur wird nachvollziehbar und einheitlich zitiert. | C34: =OFFSET(Bewertungen!E28,Bewertungen!$AS$10,0) -> 0
B35: Die Einteilung in Absätze unter stützt das Textverständnis. | C35: =OFFSET(Bewertungen!E29,Bewertungen!$AS$10,0) -> 0
B36: Die Texte sind weitestgehend fehlerfrei in Bezug auf Rechtschreibung, Zeichensetzung und Grammatik. | C36: =OFFSET(Bewertungen!E30,Bewertungen!$AS$10,0) -> 0

Sheet Stud3
A1: Übung | B1: =Uebung!B3 -> 0
A2: Leitung | B2: =Uebung!B4 -> 0
A3: Nummer | B3: =Uebung!B5 -> 0
A5: Nachname | B5: =OFFSET(Bewertungen!$F$7,Bewertungen!$AS$10,0) -> 0
A6: Vorname | B6: =OFFSET(Bewertungen!$F$8,Bewertungen!$AS$10,0) -> 0
A8: Sie können max. 100 Punkte erreichen. Je Kriterium max. 5 Punkte.
A9: Punktwerte bedeuten: | B9: 4–5= vollständig erkennbar
B10: 2–3 = weitgehend erkennbar
B11: 1 = erste Ansätze erkennbar
B12: 0 = nicht erkennbar
B13: Ihre Gesamtpunktzahl: | C13: =OFFSET(Bewertungen!$F$32,Bewertungen!$AS$10,0) -> 0
A15: Artefakt | B15: Kriterien | C15: Punkte
A17: Fragestellung (Artefakt 1a) | B17: Es liegt eine präzise formulierte Fragestellung vor, die sich auf ein konkretes Thema bezieht. | C17: =OFFSET(Bewertungen!F11,Bewertungen!$AS$10,0) -> 0
A18: Reflexionen (Artefakt 1b, 2d, 3 und 4) | B18: Es wird deutlich, dass eine bewusste Beschäftigung mit dem Thema stattgefunden hat. | C18: =OFFSET(Bewertungen!F12,Bewertungen!$AS$10,0) -> 0
B19: Die Ausgangslage der Reflexion wird beschrieben. | C19: =OFFSET(Bewertungen!F13,Bewertungen!$AS$10,0) -> 0
B20: Die beschriebene Ausgangslage wird analysiert. | C20: =OFFSET(Bewertungen!F14,Bewertungen!$AS$10,0) -> 0
B21: Es werden Verbindungen zwischen Lernerfahrungen hergestellt, z. B. zwischen aktuellen und früheren oder zwischen verschiedenen Lernsituationen etc. | C21: =OFFSET(Bewertungen!F15,Bewertungen!$AS$10,0) -> 0
B22: Vorhandene Vorannahmen, Vorurteile und Stereotype etc. werden hinterfragt. | C22: =OFFSET(Bewertungen!F16,Bewertungen!$AS$10,0) -> 0
B23: Es wird deutlich, dass der*die Schreibende zu neuen Erkenntnissen gelangt ist. | C23: =OFFSET(Bewertungen!F17,Bewertungen!$AS$10,0) -> 0
B24: Aus diesen neuen Erkenntnissen werden Implikationen für das zukünftige Denken und Handeln abgeleitet. | C24: =OFFSET(Bewertungen!F18,Bewertungen!$AS$10,0) -> 0
A25: Response Paper (Artefakt 2a-c) | B25: Arbeitet die wesentlichen Thesen des Artikels präzise heraus. | C25: =OFFSET(Bewertungen!F19,Bewertungen!$AS$10,0) -> 0
B26: Belegt die herausgearbeiteten Thesen mit Verweisen auf den Text | C26: =OFFSET(Bewertungen!F20,Bewertungen!$AS$10,0) -> 0
B27: Ordnet die herausgearbeiteten Thesen anhand weiterer Literatur ein. | C27: =OFFSET(Bewertungen!F21,Bewertungen!$AS$10,0) -> 0
B28: Bezieht kontextuelle Informationen zum Text (z. B. Lebensdaten des/der Autor*in, Denkschule, geschichtliche Einordnung, Zielpublikum) in die Einordnung ein. | C28: =OFFSET(Bewertungen!F22,Bewertungen!$AS$10,0) -> 0
B29: Positioniert sich gegenüber der herausgearbeiteten These. | C29: =OFFSET(Bewertungen!F23,Bewertungen!$AS$10,0) -> 0
B30: Begründet diese Stellung mit einer nachvollziehbaren und schlüssigen Argumentation. | C30: =OFFSET(Bewertungen!F24,Bewertungen!$AS$10,0) -> 0
B31: Der sprachliche Ausdruck ist einem wissenschaftlichen Text angemessen. | C31: =OFFSET(Bewertungen!F25,Bewertungen!$AS$10,0) -> 0
A32: gesamtes Portfolio | B32: Die Texte sind für Lesende verständlich und nachvollziehbar geschrieben. | C32: =OFFSET(Bewertungen!F26,Bewertungen!$AS$10,0) -> 0
B33: Intertextualität ist im Text transparent und nachvollziehbar formuliert. D. h. es ist durchgängig klar/eindeutig zuzuordnen, wer „spricht“, d.h. wessen Position/Meinung/ Beitrag referiert wird bzw. ob der/die Autor*in selbst „spricht“. | C33: =OFFSET(Bewertungen!F27,Bewertungen!$AS$10,0) -> 0
B34: Die verwendete Literatur wird nachvollziehbar und einheitlich zitiert. | C34: =OFFSET(Bewertungen!F28,Bewertungen!$AS$10,0) -> 0
B35: Die Einteilung in Absätze unter stützt das Textverständnis. | C35: =OFFSET(Bewertungen!F29,Bewertungen!$AS$10,0) -> 0
B36: Die Texte sind weitestgehend fehlerfrei in Bezug auf Rechtschreibung, Zeichensetzung und Grammatik. | C36: =OFFSET(Bewertungen!F30,Bewertungen!$AS$10,0) -> 0

Sheet Stud4
A1: Übung | B1: =Uebung!B3 -> 0
A2: Leitung | B2: =Uebung!B4 -> 0
A3: Nummer | B3: =Uebung!B5 -> 0
A5: Nachname | B5: =OFFSET(Bewertungen!$G$7,Bewertungen!$AS$10,0) -> 0
A6: Vorname | B6: =OFFSET(Bewertungen!$G$8,Bewertungen!$AS$10,0) -> 0
A8: Sie können max. 100 Punkte erreichen. Je Kriterium max. 5 Punkte.
A9: Punktwerte bedeuten: | B9: 4–5= vollständig erkennbar
B10: 2–3 = weitgehend erkennbar
B11: 1 = erste Ansätze erkennbar
B12: 0 = nicht erkennbar
B13: Ihre Gesamtpunktzahl: | C13: =OFFSET(Bewertungen!$G$32,Bewertungen!$AS$10,0) -> 0
A15: Artefakt | B15: Kriterien | C15: Punkte
A17: Fragestellung (Artefakt 1a) | B17: Es liegt eine präzise formulierte Fragestellung vor, die sich auf ein konkretes Thema bezieht. | C17: =OFFSET(Bewertungen!G11,Bewertungen!$AS$10,0) -> 0
A18: Reflexionen (Artefakt 1b, 2d, 3 und 4) | B18: Es wird deutlich, dass eine bewusste Beschäftigung mit dem Thema stattgefunden hat. | C18: =OFFSET(Bewertungen!G12,Bewertungen!$AS$10,0) -> 0
B19: Die Ausgangslage der Reflexion wird beschrieben. | C19: =OFFSET(Bewertungen!G13,Bewertungen!$AS$10,0) -> 0
B20: Die beschriebene Ausgangslage wird analysiert. | C20: =OFFSET(Bewertungen!G14,Bewertungen!$AS$10,0) -> 0
B21: Es werden Verbindungen zwischen Lernerfahrungen hergestellt, z. B. zwischen aktuellen und früheren oder zwischen verschiedenen Lernsituationen etc. | C21: =OFFSET(Bewertungen!G15,Bewertungen!$AS$10,0) -> 0
B22: Vorhandene Vorannahmen, Vorurteile und Stereotype etc. werden hinterfragt. | C22: =OFFSET(Bewertungen!G16,Bewertungen!$AS$10,0) -> 0
B23: Es wird deutlich, dass der*die Schreibende zu neuen Erkenntnissen gelangt ist. | C23: =OFFSET(Bewertungen!G17,Bewertungen!$AS$10,0) -> 0
B24: Aus diesen neuen Erkenntnissen werden Implikationen für das zukünftige Denken und Handeln abgeleitet. | C24: =OFFSET(Bewertungen!G18,Bewertungen!$AS$10,0) -> 0
A25: Response Paper (Artefakt 2a-c) | B25: Arbeitet die wesentlichen Thesen des Artikels präzise heraus. | C25: =OFFSET(Bewertungen!G19,Bewertungen!$AS$10,0) -> 0
B26: Belegt die herausgearbeiteten Thesen mit Verweisen auf den Text | C26: =OFFSET(Bewertungen!G20,Bewertungen!$AS$10,0) -> 0
B27: Ordnet die herausgearbeiteten Thesen anhand weiterer Literatur ein. | C27: =OFFSET(Bewertungen!G21,Bewertungen!$AS$10,0) -> 0
B28: Bezieht kontextuelle Informationen zum Text (z. B. Lebensdaten des/der Autor*in, Denkschule, geschichtliche Einordnung, Zielpublikum) in die Einordnung ein. | C28: =OFFSET(Bewertungen!G22,Bewertungen!$AS$10,0) -> 0
B29: Positioniert sich gegenüber der herausgearbeiteten These. | C29: =OFFSET(Bewertungen!G23,Bewertungen!$AS$10,0) -> 0
B30: Begründet diese Stellung mit einer nachvollziehbaren und schlüssigen Argumentation. | C30: =OFFSET(Bewertungen!G24,Bewertungen!$AS$10,0) -> 0
B31: Der sprachliche Ausdruck ist einem wissenschaftlichen Text angemessen. | C31: =OFFSET(Bewertungen!G25,Bewertungen!$AS$10,0) -> 0
A32: gesamtes Portfolio | B32: Die Texte sind für Lesende verständlich und nachvollziehbar geschrieben. | C32: =OFFSET(Bewertungen!G26,Bewertungen!$AS$10,0) -> 0
B33: Intertextualität ist im Text transparent und nachvollziehbar formuliert. D. h. es ist durchgängig klar/eindeutig zuzuordnen, wer „spricht“, d.h. wessen Position/Meinung/ Beitrag referiert wird bzw. ob der/die Autor*in selbst „spricht“. | C33: =OFFSET(Bewertungen!G27,Bewertungen!$AS$10,0) -> 0
B34: Die verwendete Literatur wird nachvollziehbar und einheitlich zitiert. | C34: =OFFSET(Bewertungen!G28,Bewertungen!$AS$10,0) -> 0
B35: Die Einteilung in Absätze unter stützt das Textverständnis. | C35: =OFFSET(Bewertungen!G29,Bewertungen!$AS$10,0) -> 0
B36: Die Texte sind weitestgehend fehlerfrei in Bezug auf Rechtschreibung, Zeichensetzung und Grammatik. | C36: =OFFSET(Bewertungen!G30,Bewertungen!$AS$10,0) -> 0

Sheet Stud5
A1: Übung | B1: =Uebung!B3 -> 0
A2: Leitung | B2: =Uebung!B4 -> 0
A3: Nummer | B3: =Uebung!B5 -> 0
A5: Nachname | B5: =OFFSET(Bewertungen!$H$7,Bewertungen!$AS$10,0) -> 0
A6: Vorname | B6: =OFFSET(Bewertungen!$H$8,Bewertungen!$AS$10,0) -> 0
A8: Sie können max. 100 Punkte erreichen. Je Kriterium max. 5 Punkte.
A9: Punktwerte bedeuten: | B9: 4–5= vollständig erkennbar
B10: 2–3 = weitgehend erkennbar
B11: 1 = erste Ansätze erkennbar
B12: 0 = nicht erkennbar
B13: Ihre Gesamtpunktzahl: | C13: =OFFSET(Bewertungen!$H$32,Bewertungen!$AS$10,0) -> 0
A15: Artefakt | B15: Kriterien | C15: Punkte
A17: Fragestellung (Artefakt 1a) | B17: Es liegt eine präzise formulierte Fragestellung vor, die sich auf ein konkretes Thema bezieht. | C17: =OFFSET(Bewertungen!H11,Bewertungen!$AS$10,0) -> 0
A18: Reflexionen (Artefakt 1b, 2d, 3 und 4) | B18: Es wird deutlich, dass eine bewusste Beschäftigung mit dem Thema stattgefunden hat. | C18: =OFFSET(Bewertungen!H12,Bewertungen!$AS$10,0) -> 0
B19: Die Ausgangslage der Reflexion wird beschrieben. | C19: =OFFSET(Bewertungen!H13,Bewertungen!$AS$10,0) -> 0
B20: Die beschriebene Ausgangslage wird analysiert. | C20: =OFFSET(Bewertungen!H14,Bewertungen!$AS$10,0) -> 0
B21: Es werden Verbindungen zwischen Lernerfahrungen hergestellt, z. B. zwischen aktuellen und früheren oder zwischen verschiedenen Lernsituationen etc. | C21: =OFFSET(Bewertungen!H15,Bewertungen!$AS$10,0) -> 0
B22: Vorhandene Vorannahmen, Vorurteile und Stereotype etc. werden hinterfragt. | C22: =OFFSET(Bewertungen!H16,Bewertungen!$AS$10,0) -> 0
B23: Es wird deutlich, dass der*die Schreibende zu neuen Erkenntnissen gelangt ist. | C23: =OFFSET(Bewertungen!H17,Bewertungen!$AS$10,0) -> 0
B24: Aus diesen neuen Erkenntnissen werden Implikationen für das zukünftige Denken und Handeln abgeleitet. | C24: =OFFSET(Bewertungen!H18,Bewertungen!$AS$10,0) -> 0
A25: Response Paper (Artefakt 2a-c) | B25: Arbeitet die wesentlichen Thesen des Artikels präzise heraus. | C25: =OFFSET(Bewertungen!H19,Bewertungen!$AS$10,0) -> 0
B26: Belegt die herausgearbeiteten Thesen mit Verweisen auf den Text | C26: =OFFSET(Bewertungen!H20,Bewertungen!$AS$10,0) -> 0
B27: Ordnet die herausgearbeiteten Thesen anhand weiterer Literatur ein. | C27: =OFFSET(Bewertungen!H21,Bewertungen!$AS$10,0) -> 0
B28: Bezieht kontextuelle Informationen zum Text (z. B. Lebensdaten des/der Autor*in, Denkschule, geschichtliche Einordnung, Zielpublikum) in die Einordnung ein. | C28: =OFFSET(Bewertungen!H22,Bewertungen!$AS$10,0) -> 0
B29: Positioniert sich gegenüber der herausgearbeiteten These. | C29: =OFFSET(Bewertungen!H23,Bewertungen!$AS$10,0) -> 0
B30: Begründet diese Stellung mit einer nachvollziehbaren und schlüssigen Argumentation. | C30: =OFFSET(Bewertungen!H24,Bewertungen!$AS$10,0) -> 0
B31: Der sprachliche Ausdruck ist einem wissenschaftlichen Text angemessen. | C31: =OFFSET(Bewertungen!H25,Bewertungen!$AS$10,0) -> 0
A32: gesamtes Portfolio | B32: Die Texte sind für Lesende verständlich und nachvollziehbar geschrieben. | C32: =OFFSET(Bewertungen!H26,Bewertungen!$AS$10,0) -> 0
B33: Intertextualität ist im Text transparent und nachvollziehbar formuliert. D. h. es ist durchgängig klar/eindeutig zuzuordnen, wer „spricht“, d.h. wessen Position/Meinung/ Beitrag referiert wird bzw. ob der/die Autor*in selbst „spricht“. | C33: =OFFSET(Bewertungen!H27,Bewertungen!$AS$10,0) -> 0
B34: Die verwendete Literatur wird nachvollziehbar und einheitlich zitiert. | C34: =OFFSET(Bewertungen!H28,Bewertungen!$AS$10,0) -> 0
B35: Die Einteilung in Absätze unter stützt das Textverständnis. | C35: =OFFSET(Bewertungen!H29,Bewertungen!$AS$10,0) -> 0
B36: Die Texte sind weitestgehend fehlerfrei in Bezug auf Rechtschreibung, Zeichensetzung und Grammatik. | C36: =OFFSET(Bewertungen!H30,Bewertungen!$AS$10,0) -> 0

Sheet Stud6
A1: Übung | B1: =Uebung!B3 -> 0
A2: Leitung | B2: =Uebung!B4 -> 0
A3: Nummer | B3: =Uebung!B5 -> 0
A5: Nachname | B5: =OFFSET(Bewertungen!$I$7,Bewertungen!$AS$10,0) -> 0
A6: Vorname | B6: =OFFSET(Bewertungen!$I$8,Bewertungen!$AS$10,0) -> 0
A8: Sie können max. 100 Punkte erreichen. Je Kriterium max. 5 Punkte.
A9: Punktwerte bedeuten: | B9: 4–5= vollständig erkennbar
B10: 2–3 = weitgehend erkennbar
B11: 1 = erste Ansätze erkennbar
B12: 0 = nicht erkennbar
B13: Ihre Gesamtpunktzahl: | C13: =OFFSET(Bewertungen!$I$32,Bewertungen!$AS$10,0) -> 0
A15: Artefakt | B15: Kriterien | C15: Punkte
A17: Fragestellung (Artefakt 1a) | B17: Es liegt eine präzise formulierte Fragestellung vor, die sich auf ein konkretes Thema bezieht. | C17: =OFFSET(Bewertungen!I11,Bewertungen!$AS$10,0) -> 0
A18: Reflexionen (Artefakt 1b, 2d, 3 und 4) | B18: Es wird deutlich, dass eine bewusste Beschäftigung mit dem Thema stattgefunden hat. | C18: =OFFSET(Bewertungen!I12,Bewertungen!$AS$10,0) -> 0
B19: Die Ausgangslage der Reflexion wird beschrieben. | C19: =OFFSET(Bewertungen!I13,Bewertungen!$AS$10,0) -> 0
B20: Die beschriebene Ausgangslage wird analysiert. | C20: =OFFSET(Bewertungen!I14,Bewertungen!$AS$10,0) -> 0
B21: Es werden Verbindungen zwischen Lernerfahrungen hergestellt, z. B. zwischen aktuellen und früheren oder zwischen verschiedenen Lernsituationen etc. | C21: =OFFSET(Bewertungen!I15,Bewertungen!$AS$10,0) -> 0
B22: Vorhandene Vorannahmen, Vorurteile und Stereotype etc. werden hinterfragt. | C22: =OFFSET(Bewertungen!I16,Bewertungen!$AS$10,0) -> 0
B23: Es wird deutlich, dass der*die Schreibende zu neuen Erkenntnissen gelangt ist. | C23: =OFFSET(Bewertungen!I17,Bewertungen!$AS$10,0) -> 0
B24: Aus diesen neuen Erkenntnissen werden Implikationen für das zukünftige Denken und Handeln abgeleitet. | C24: =OFFSET(Bewertungen!I18,Bewertungen!$AS$10,0) -> 0
A25: Response Paper (Artefakt 2a-c) | B25: Arbeitet die wesentlichen Thesen des Artikels präzise heraus. | C25: =OFFSET(Bewertungen!I19,Bewertungen!$AS$10,0) -> 0
B26: Belegt die herausgearbeiteten Thesen mit Verweisen auf den Text | C26: =OFFSET(Bewertungen!I20,Bewertungen!$AS$10,0) -> 0
B27: Ordnet die herausgearbeiteten Thesen anhand weiterer Literatur ein. | C27: =OFFSET(Bewertungen!I21,Bewertungen!$AS$10,0) -> 0
B28: Bezieht kontextuelle Informationen zum Text (z. B. Lebensdaten des/der Autor*in, Denkschule, geschichtliche Einordnung, Zielpublikum) in die Einordnung ein. | C28: =OFFSET(Bewertungen!I22,Bewertungen!$AS$10,0) -> 0
B29: Positioniert sich gegenüber der herausgearbeiteten These. | C29: =OFFSET(Bewertungen!I23,Bewertungen!$AS$10,0) -> 0
B30: Begründet diese Stellung mit einer nachvollziehbaren und schlüssigen Argumentation. | C30: =OFFSET(Bewertungen!I24,Bewertungen!$AS$10,0) -> 0
B31: Der sprachliche Ausdruck ist einem wissenschaftlichen Text angemessen. | C31: =OFFSET(Bewertungen!I25,Bewertungen!$AS$10,0) -> 0
A32: gesamtes Portfolio | B32: Die Texte sind für Lesende verständlich und nachvollziehbar geschrieben. | C32: =OFFSET(Bewertungen!I26,Bewertungen!$AS$10,0) -> 0
B33: Intertextualität ist im Text transparent und nachvollziehbar formuliert. D. h. es ist durchgängig klar/eindeutig zuzuordnen, wer „spricht“, d.h. wessen Position/Meinung/ Beitrag referiert wird bzw. ob der/die Autor*in selbst „spricht“. | C33: =OFFSET(Bewertungen!I27,Bewertungen!$AS$10,0) -> 0
B34: Die verwendete Literatur wird nachvollziehbar und einheitlich zitiert. | C34: =OFFSET(Bewertungen!I28,Bewertungen!$AS$10,0) -> 0
B35: Die Einteilung in Absätze unter stützt das Textverständnis. | C35: =OFFSET(Bewertungen!I29,Bewertungen!$AS$10,0) -> 0
B36: Die Texte sind weitestgehend fehlerfrei in Bezug auf Rechtschreibung, Zeichensetzung und Grammatik. | C36: =OFFSET(Bewertungen!I30,Bewertungen!$AS$10,0) -> 0

Sheet Stud7
A1: Übung | B1: =Uebung!B3 -> 0
A2: Leitung | B2: =Uebung!B4 -> 0
A3: Nummer | B3: =Uebung!B5 -> 0
A5: Nachname | B5: =OFFSET(Bewertungen!$J$7,Bewertungen!$AS$10,0) -> 0
A6: Vorname | B6: =OFFSET(Bewertungen!$J$8,Bewertungen!$AS$10,0) -> 0
A8: Sie können max. 100 Punkte erreichen. Je Kriterium max. 5 Punkte.
A9: Punktwerte bedeuten: | B9: 4–5= vollständig erkennbar
B10: 2–3 = weitgehend erkennbar
B11: 1 = erste Ansätze erkennbar
B12: 0 = nicht erkennbar
B13: Ihre Gesamtpunktzahl: | C13: =OFFSET(Bewertungen!$J$32,Bewertungen!$AS$10,0) -> 0
A15: Artefakt | B15: Kriterien | C15: Punkte
A17: Fragestellung (Artefakt 1a) | B17: Es liegt eine präzise formulierte Fragestellung vor, die sich auf ein konkretes Thema bezieht. | C17: =OFFSET(Bewertungen!J11,Bewertungen!$AS$10,0) -> 0
A18: Reflexionen (Artefakt 1b, 2d, 3 und 4) | B18: Es wird deutlich, dass eine bewusste Beschäftigung mit dem Thema stattgefunden hat. | C18: =OFFSET(Bewertungen!J12,Bewertungen!$AS$10,0) -> 0
B19: Die Ausgangslage der Reflexion wird beschrieben. | C19: =OFFSET(Bewertungen!J13,Bewertungen!$AS$10,0) -> 0
B20: Die beschriebene Ausgangslage wird analysiert. | C20: =OFFSET(Bewertungen!J14,Bewertungen!$AS$10,0) -> 0
B21: Es werden Verbindungen zwischen Lernerfahrungen hergestellt, z. B. zwischen aktuellen und früheren oder zwischen verschiedenen Lernsituationen etc. | C21: =OFFSET(Bewertungen!J15,Bewertungen!$AS$10,0) -> 0
B22: Vorhandene Vorannahmen, Vorurteile und Stereotype etc. werden hinterfragt. | C22: =OFFSET(Bewertungen!J16,Bewertungen!$AS$10,0) -> 0
B23: Es wird deutlich, dass der*die Schreibende zu neuen Erkenntnissen gelangt ist. | C23: =OFFSET(Bewertungen!J17,Bewertungen!$AS$10,0) -> 0
B24: Aus diesen neuen Erkenntnissen werden Implikationen für das zukünftige Denken und Handeln abgeleitet. | C24: =OFFSET(Bewertungen!J18,Bewertungen!$AS$10,0) -> 0
A25: Response Paper (Artefakt 2a-c) | B25: Arbeitet die wesentlichen Thesen des Artikels präzise heraus. | C25: =OFFSET(Bewertungen!J19,Bewertungen!$AS$10,0) -> 0
B26: Belegt die herausgearbeiteten Thesen mit Verweisen auf den Text | C26: =OFFSET(Bewertungen!J20,Bewertungen!$AS$10,0) -> 0
B27: Ordnet die herausgearbeiteten Thesen anhand weiterer Literatur ein. | C27: =OFFSET(Bewertungen!J21,Bewertungen!$AS$10,0) -> 0
B28: Bezieht kontextuelle Informationen zum Text (z. B. Lebensdaten des/der Autor*in, Denkschule, geschichtliche Einordnung, Zielpublikum) in die Einordnung ein. | C28: =OFFSET(Bewertungen!J22,Bewertungen!$AS$10,0) -> 0
B29: Positioniert sich gegenüber der herausgearbeiteten These. | C29: =OFFSET(Bewertungen!J23,Bewertungen!$AS$10,0) -> 0
B30: Begründet diese Stellung mit einer nachvollziehbaren und schlüssigen Argumentation. | C30: =OFFSET(Bewertungen!J24,Bewertungen!$AS$10,0) -> 0
B31: Der sprachliche Ausdruck ist einem wissenschaftlichen Text angemessen. | C31: =OFFSET(Bewertungen!J25,Bewertungen!$AS$10,0) -> 0
A32: gesamtes Portfolio | B32: Die Texte sind für Lesende verständlich und nachvollziehbar geschrieben. | C32: =OFFSET(Bewertungen!J26,Bewertungen!$AS$10,0) -> 0
B33: Intertextualität ist im Text transparent und nachvollziehbar formuliert. D. h. es ist durchgängig klar/eindeutig zuzuordnen, wer „spricht“, d.h. wessen Position/Meinung/ Beitrag referiert wird bzw. ob der/die Autor*in selbst „spricht“. | C33: =OFFSET(Bewertungen!J27,Bewertungen!$AS$10,0) -> 0
B34: Die verwendete Literatur wird nachvollziehbar und einheitlich zitiert. | C34: =OFFSET(Bewertungen!J28,Bewertungen!$AS$10,0) -> 0
B35: Die Einteilung in Absätze unter stützt das Textverständnis. | C35: =OFFSET(Bewertungen!J29,Bewertungen!$AS$10,0) -> 0
B36: Die Texte sind weitestgehend fehlerfrei in Bezug auf Rechtschreibung, Zeichensetzung und Grammatik. | C36: =OFFSET(Bewertungen!J30,Bewertungen!$AS$10,0) -> 0

Sheet Stud8
A1: Übung | B1: =Uebung!B3 -> 0
A2: Leitung | B2: =Uebung!B4 -> 0
A3: Nummer | B3: =Uebung!B5 -> 0
A5: Nachname | B5: =OFFSET(Bewertungen!$K$7,Bewertungen!$AS$10,0) -> 0
A6: Vorname | B6: =OFFSET(Bewertungen!$K$8,Bewertungen!$AS$10,0) -> 0
A8: Sie können max. 100 Punkte erreichen. Je Kriterium max. 5 Punkte.
A9: Punktwerte bedeuten: | B9: 4–5= vollständig erkennbar
B10: 2–3 = weitgehend erkennbar
B11: 1 = erste Ansätze erkennbar
B12: 0 = nicht erkennbar
B13: Ihre Gesamtpunktzahl: | C13: =OFFSET(Bewertungen!$K$32,Bewertungen!$AS$10,0) -> 0
A15: Artefakt | B15: Kriterien | C15: Punkte
A17: Fragestellung (Artefakt 1a) | B17: Es liegt eine präzise formulierte Fragestellung vor, die sich auf ein konkretes Thema bezieht. | C17: =OFFSET(Bewertungen!K11,Bewertungen!$AS$10,0) -> 0
A18: Reflexionen (Artefakt 1b, 2d, 3 und 4) | B18: Es wird deutlich, dass eine bewusste Beschäftigung mit dem Thema stattgefunden hat. | C18: =OFFSET(Bewertungen!K12,Bewertungen!$AS$10,0) -> 0
B19: Die Ausgangslage der Reflexion wird beschrieben. | C19: =OFFSET(Bewertungen!K13,Bewertungen!$AS$10,0) -> 0
B20: Die beschriebene Ausgangslage wird analysiert. | C20: =OFFSET(Bewertungen!K14,Bewertungen!$AS$10,0) -> 0
B21: Es werden Verbindungen zwischen Lernerfahrungen hergestellt, z. B. zwischen aktuellen und früheren oder zwischen verschiedenen Lernsituationen etc. | C21: =OFFSET(Bewertungen!K15,Bewertungen!$AS$10,0) -> 0
B22: Vorhandene Vorannahmen, Vorurteile und Stereotype etc. werden hinterfragt. | C22: =OFFSET(Bewertungen!K16,Bewertungen!$AS$10,0) -> 0
B23: Es wird deutlich, dass der*die Schreibende zu neuen Erkenntnissen gelangt ist. | C23: =OFFSET(Bewertungen!K17,Bewertungen!$AS$10,0) -> 0
B24: Aus diesen neuen Erkenntnissen werden Implikationen für das zukünftige Denken und Handeln abgeleitet. | C24: =OFFSET(Bewertungen!K18,Bewertungen!$AS$10,0) -> 0
A25: Response Paper (Artefakt 2a-c) | B25: Arbeitet die wesentlichen Thesen des Artikels präzise heraus. | C25: =OFFSET(Bewertungen!K19,Bewertungen!$AS$10,0) -> 0
B26: Belegt die herausgearbeiteten Thesen mit Verweisen auf den Text | C26: =OFFSET(Bewertungen!K20,Bewertungen!$AS$10,0) -> 0
B27: Ordnet die herausgearbeiteten Thesen anhand weiterer Literatur ein. | C27: =OFFSET(Bewertungen!K21,Bewertungen!$AS$10,0) -> 0
B28: Bezieht kontextuelle Informationen zum Text (z. B. Lebensdaten des/der Autor*in, Denkschule, geschichtliche Einordnung, Zielpublikum) in die Einordnung ein. | C28: =OFFSET(Bewertungen!K22,Bewertungen!$AS$10,0) -> 0
B29: Positioniert sich gegenüber der herausgearbeiteten These. | C29: =OFFSET(Bewertungen!K23,Bewertungen!$AS$10,0) -> 0
B30: Begründet diese Stellung mit einer nachvollziehbaren und schlüssigen Argumentation. | C30: =OFFSET(Bewertungen!K24,Bewertungen!$AS$10,0) -> 0
B31: Der sprachliche Ausdruck ist einem wissenschaftlichen Text angemessen. | C31: =OFFSET(Bewertungen!K25,Bewertungen!$AS$10,0) -> 0
A32: gesamtes Portfolio | B32: Die Texte sind für Lesende verständlich und nachvollziehbar geschrieben. | C32: =OFFSET(Bewertungen!K26,Bewertungen!$AS$10,0) -> 0
B33: Intertextualität ist im Text transparent und nachvollziehbar formuliert. D. h. es ist durchgängig klar/eindeutig zuzuordnen, wer „spricht“, d.h. wessen Position/Meinung/ Beitrag referiert wird bzw. ob der/die Autor*in selbst „spricht“. | C33: =OFFSET(Bewertungen!K27,Bewertungen!$AS$10,0) -> 0
B34: Die verwendete Literatur wird nachvollziehbar und einheitlich zitiert. | C34: =OFFSET(Bewertungen!K28,Bewertungen!$AS$10,0) -> 0
B35: Die Einteilung in Absätze unter stützt das Textverständnis. | C35: =OFFSET(Bewertungen!K29,Bewertungen!$AS$10,0) -> 0
B36: Die Texte sind weitestgehend fehlerfrei in Bezug auf Rechtschreibung, Zeichensetzung und Grammatik. | C36: =OFFSET(Bewertungen!K30,Bewertungen!$AS$10,0) -> 0

Sheet Stud9
A1: Übung | B1: =Uebung!B3 -> 0
A2: Leitung | B2: =Uebung!B4 -> 0
A3: Nummer | B3: =Uebung!B5 -> 0
A5: Nachname | B5: =OFFSET(Bewertungen!$L$7,Bewertungen!$AS$10,0) -> 0
A6: Vorname | B6: =OFFSET(Bewertungen!$L$8,Bewertungen!$AS$10,0) -> 0
A8: Sie können max. 100 Punkte erreichen. Je Kriterium max. 5 Punkte.
A9: Punktwerte bedeuten: | B9: 4–5= vollständig erkennbar
B10: 2–3 = weitgehend erkennbar
B11: 1 = erste Ansätze erkennbar
B12: 0 = nicht erkennbar
B13: Ihre Gesamtpunktzahl: | C13: =OFFSET(Bewertungen!$L$32,Bewertungen!$AS$10,0) -> 0
A15: Artefakt | B15: Kriterien | C15: Punkte
A17: Fragestellung (Artefakt 1a) | B17: Es liegt eine präzise formulierte Fragestellung vor, die sich auf ein konkretes Thema bezieht. | C17: =OFFSET(Bewertungen!L11,Bewertungen!$AS$10,0) -> 0
A18: Reflexionen (Artefakt 1b, 2d, 3 und 4) | B18: Es wird deutlich, dass eine bewusste Beschäftigung mit dem Thema stattgefunden hat. | C18: =OFFSET(Bewertungen!L12,Bewertungen!$AS$10,0) -> 0
B19: Die Ausgangslage der Reflexion wird beschrieben. | C19: =OFFSET(Bewertungen!L13,Bewertungen!$AS$10,0) -> 0
B20: Die beschriebene Ausgangslage wird analysiert. | C20: =OFFSET(Bewertungen!L14,Bewertungen!$AS$10,0) -> 0
B21: Es werden Verbindungen zwischen Lernerfahrungen hergestellt, z. B. zwischen aktuellen und früheren oder zwischen verschiedenen Lernsituationen etc. | C21: =OFFSET(Bewertungen!L15,Bewertungen!$AS$10,0) -> 0
B22: Vorhandene Vorannahmen, Vorurteile und Stereotype etc. werden hinterfragt. | C22: =OFFSET(Bewertungen!L16,Bewertungen!$AS$10,0) -> 0
B23: Es wird deutlich, dass der*die Schreibende zu neuen Erkenntnissen gelangt ist. | C23: =OFFSET(Bewertungen!L17,Bewertungen!$AS$10,0) -> 0
B24: Aus diesen neuen Erkenntnissen werden Implikationen für das zukünftige Denken und Handeln abgeleitet. | C24: =OFFSET(Bewertungen!L18,Bewertungen!$AS$10,0) -> 0
A25: Response Paper (Artefakt 2a-c) | B25: Arbeitet die wesentlichen Thesen des Artikels präzise heraus. | C25: =OFFSET(Bewertungen!L19,Bewertungen!$AS$10,0) -> 0
B26: Belegt die herausgearbeiteten Thesen mit Verweisen auf den Text | C26: =OFFSET(Bewertungen!L20,Bewertungen!$AS$10,0) -> 0
B27: Ordnet die herausgearbeiteten Thesen anhand weiterer Literatur ein. | C27: =OFFSET(Bewertungen!L21,Bewertungen!$AS$10,0) -> 0
B28: Bezieht kontextuelle Informationen zum Text (z. B. Lebensdaten des/der Autor*in, Denkschule, geschichtliche Einordnung, Zielpublikum) in die Einordnung ein. | C28: =OFFSET(Bewertungen!L22,Bewertungen!$AS$10,0) -> 0
B29: Positioniert sich gegenüber der herausgearbeiteten These. | C29: =OFFSET(Bewertungen!L23,Bewertungen!$AS$10,0) -> 0
B30: Begründet diese Stellung mit einer nachvollziehbaren und schlüssigen Argumentation. | C30: =OFFSET(Bewertungen!L24,Bewertungen!$AS$10,0) -> 0
B31: Der sprachliche Ausdruck ist einem wissenschaftlichen Text angemessen. | C31: =OFFSET(Bewertungen!L25,Bewertungen!$AS$10,0) -> 0
A32: gesamtes Portfolio | B32: Die Texte sind für Lesende verständlich und nachvollziehbar geschrieben. | C32: =OFFSET(Bewertungen!L26,Bewertungen!$AS$10,0) -> 0
B33: Intertextualität ist im Text transparent und nachvollziehbar formuliert. D. h. es ist durchgängig klar/eindeutig zuzuordnen, wer „spricht“, d.h. wessen Position/Meinung/ Beitrag referiert wird bzw. ob der/die Autor*in selbst „spricht“. | C33: =OFFSET(Bewertungen!L27,Bewertungen!$AS$10,0) -> 0
B34: Die verwendete Literatur wird nachvollziehbar und einheitlich zitiert. | C34: =OFFSET(Bewertungen!L28,Bewertungen!$AS$10,0) -> 0
B35: Die Einteilung in Absätze unter stützt das Textverständnis. | C35: =OFFSET(Bewertungen!L29,Bewertungen!$AS$10,0) -> 0
B36: Die Texte sind weitestgehend fehlerfrei in Bezug auf Rechtschreibung, Zeichensetzung und Grammatik. | C36: =OFFSET(Bewertungen!L30,Bewertungen!$AS$10,0) -> 0

Sheet Stud10
A1: Übung | B1: =Uebung!B3 -> 0
A2: Leitung | B2: =Uebung!B4 -> 0
A3: Nummer | B3: =Uebung!B5 -> 0
A5: Nachname | B5: =OFFSET(Bewertungen!$M$7,Bewertungen!$AS$10,0) -> 0
A6: Vorname | B6: =OFFSET(Bewertungen!$M$8,Bewertungen!$AS$10,0) -> 0
A8: Sie können max. 100 Punkte erreichen. Je Kriterium max. 5 Punkte.
A9: Punktwerte bedeuten: | B9: 4–5= vollständig erkennbar
B10: 2–3 = weitgehend erkennbar
B11: 1 = erste Ansätze erkennbar
B12: 0 = nicht erkennbar
B13: Ihre Gesamtpunktzahl: | C13: =OFFSET(Bewertungen!$M$32,Bewertungen!$AS$10,0) -> 0
A15: Artefakt | B15: Kriterien | C15: Punkte
A17: Fragestellung (Artefakt 1a) | B17: Es liegt eine präzise formulierte Fragestellung vor, die sich auf ein konkretes Thema bezieht. | C17: =OFFSET(Bewertungen!M11,Bewertungen!$AS$10,0) -> 0
A18: Reflexionen (Artefakt 1b, 2d, 3 und 4) | B18: Es wird deutlich, dass eine bewusste Beschäftigung mit dem Thema stattgefunden hat. | C18: =OFFSET(Bewertungen!M12,Bewertungen!$AS$10,0) -> 0
B19: Die Ausgangslage der Reflexion wird beschrieben. | C19: =OFFSET(Bewertungen!M13,Bewertungen!$AS$10,0) -> 0
B20: Die beschriebene Ausgangslage wird analysiert. | C20: =OFFSET(Bewertungen!M14,Bewertungen!$AS$10,0) -> 0
B21: Es werden Verbindungen zwischen Lernerfahrungen hergestellt, z. B. zwischen aktuellen und früheren oder zwischen verschiedenen Lernsituationen etc. | C21: =OFFSET(Bewertungen!M15,Bewertungen!$AS$10,0) -> 0
B22: Vorhandene Vorannahmen, Vorurteile und Stereotype etc. werden hinterfragt. | C22: =OFFSET(Bewertungen!M16,Bewertungen!$AS$10,0) -> 0
B23: Es wird deutlich, dass der*die Schreibende zu neuen Erkenntnissen gelangt ist. | C23: =OFFSET(Bewertungen!M17,Bewertungen!$AS$10,0) -> 0
B24: Aus diesen neuen Erkenntnissen werden Implikationen für das zukünftige Denken und Handeln abgeleitet. | C24: =OFFSET(Bewertungen!M18,Bewertungen!$AS$10,0) -> 0
A25: Response Paper (Artefakt 2a-c) | B25: Arbeitet die wesentlichen Thesen des Artikels präzise heraus. | C25: =OFFSET(Bewertungen!M19,Bewertungen!$AS$10,0) -> 0
B26: Belegt die herausgearbeiteten Thesen mit Verweisen auf den Text | C26: =OFFSET(Bewertungen!M20,Bewertungen!$AS$10,0) -> 0
B27: Ordnet die herausgearbeiteten Thesen anhand weiterer Literatur ein. | C27: =OFFSET(Bewertungen!M21,Bewertungen!$AS$10,0) -> 0
B28: Bezieht kontextuelle Informationen zum Text (z. B. Lebensdaten des/der Autor*in, Denkschule, geschichtliche Einordnung, Zielpublikum) in die Einordnung ein. | C28: =OFFSET(Bewertungen!M22,Bewertungen!$AS$10,0) -> 0
B29: Positioniert sich gegenüber der herausgearbeiteten These. | C29: =OFFSET(Bewertungen!M23,Bewertungen!$AS$10,0) -> 0
B30: Begründet diese Stellung mit einer nachvollziehbaren und schlüssigen Argumentation. | C30: =OFFSET(Bewertungen!M24,Bewertungen!$AS$10,0) -> 0
B31: Der sprachliche Ausdruck ist einem wissenschaftlichen Text angemessen. | C31: =OFFSET(Bewertungen!M25,Bewertungen!$AS$10,0) -> 0
A32: gesamtes Portfolio | B32: Die Texte sind für Lesende verständlich und nachvollziehbar geschrieben. | C32: =OFFSET(Bewertungen!M26,Bewertungen!$AS$10,0) -> 0
B33: Intertextualität ist im Text transparent und nachvollziehbar formuliert. D. h. es ist durchgängig klar/eindeutig zuzuordnen, wer „spricht“, d.h. wessen Position/Meinung/ Beitrag referiert wird bzw. ob der/die Autor*in selbst „spricht“. | C33: =OFFSET(Bewertungen!M27,Bewertungen!$AS$10,0) -> 0
B34: Die verwendete Literatur wird nachvollziehbar und einheitlich zitiert. | C34: =OFFSET(Bewertungen!M28,Bewertungen!$AS$10,0) -> 0
B35: Die Einteilung in Absätze unter stützt das Textverständnis. | C35: =OFFSET(Bewertungen!M29,Bewertungen!$AS$10,0) -> 0
B36: Die Texte sind weitestgehend fehlerfrei in Bezug auf Rechtschreibung, Zeichensetzung und Grammatik. | C36: =OFFSET(Bewertungen!M30,Bewertungen!$AS$10,0) -> 0

Sheet Stud11
A1: Übung | B1: =Uebung!B3 -> 0
A2: Leitung | B2: =Uebung!B4 -> 0
A3: Nummer | B3: =Uebung!B5 -> 0
A5: Nachname | B5: =OFFSET(Bewertungen!$N$7,Bewertungen!$AS$10,0) -> 0
A6: Vorname | B6: =OFFSET(Bewertungen!$N$8,Bewertungen!$AS$10,0) -> 0
A8: Sie können max. 100 Punkte erreichen. Je Kriterium max. 5 Punkte.
A9: Punktwerte bedeuten: | B9: 4–5= vollständig erkennbar
B10: 2–3 = weitgehend erkennbar
B11: 1 = erste Ansätze erkennbar
B12: 0 = nicht erkennbar
B13: Ihre Gesamtpunktzahl: | C13: =OFFSET(Bewertungen!$N$32,Bewertungen!$AS$10,0) -> 0
A15: Artefakt | B15: Kriterien | C15: Punkte
A17: Fragestellung (Artefakt 1a) | B17: Es liegt eine präzise formulierte Fragestellung vor, die sich auf ein konkretes Thema bezieht. | C17: =OFFSET(Bewertungen!N11,Bewertungen!$AS$10,0) -> 0
A18: Reflexionen (Artefakt 1b, 2d, 3 und 4) | B18: Es wird deutlich, dass eine bewusste Beschäftigung mit dem Thema stattgefunden hat. | C18: =OFFSET(Bewertungen!N12,Bewertungen!$AS$10,0) -> 0
B19: Die Ausgangslage der Reflexion wird beschrieben. | C19: =OFFSET(Bewertungen!N13,Bewertungen!$AS$10,0) -> 0
B20: Die beschriebene Ausgangslage wird analysiert. | C20: =OFFSET(Bewertungen!N14,Bewertungen!$AS$10,0) -> 0
B21: Es werden Verbindungen zwischen Lernerfahrungen hergestellt, z. B. zwischen aktuellen und früheren oder zwischen verschiedenen Lernsituationen etc. | C21: =OFFSET(Bewertungen!N15,Bewertungen!$AS$10,0) -> 0
B22: Vorhandene Vorannahmen, Vorurteile und Stereotype etc. werden hinterfragt. | C22: =OFFSET(Bewertungen!N16,Bewertungen!$AS$10,0) -> 0
B23: Es wird deutlich, dass der*die Schreibende zu neuen Erkenntnissen gelangt ist. | C23: =OFFSET(Bewertungen!N17,Bewertungen!$AS$10,0) -> 0
B24: Aus diesen neuen Erkenntnissen werden Implikationen für das zukünftige Denken und Handeln abgeleitet. | C24: =OFFSET(Bewertungen!N18,Bewertungen!$AS$10,0) -> 0
A25: Response Paper (Artefakt 2a-c) | B25: Arbeitet die wesentlichen Thesen des Artikels präzise heraus. | C25: =OFFSET(Bewertungen!N19,Bewertungen!$AS$10,0) -> 0
B26: Belegt die herausgearbeiteten Thesen mit Verweisen auf den Text | C26: =OFFSET(Bewertungen!N20,Bewertungen!$AS$10,0) -> 0
B27: Ordnet die herausgearbeiteten Thesen anhand weiterer Literatur ein. | C27: =OFFSET(Bewertungen!N21,Bewertungen!$AS$10,0) -> 0
B28: Bezieht kontextuelle Informationen zum Text (z. B. Lebensdaten des/der Autor*in, Denkschule, geschichtliche Einordnung, Zielpublikum) in die Einordnung ein. | C28: =OFFSET(Bewertungen!N22,Bewertungen!$AS$10,0) -> 0
B29: Positioniert sich gegenüber der herausgearbeiteten These. | C29: =OFFSET(Bewertungen!N23,Bewertungen!$AS$10,0) -> 0
B30: Begründet diese Stellung mit einer nachvollziehbaren und schlüssigen Argumentation. | C30: =OFFSET(Bewertungen!N24,Bewertungen!$AS$10,0) -> 0
B31: Der sprachliche Ausdruck ist einem wissenschaftlichen Text angemessen. | C31: =OFFSET(Bewertungen!N25,Bewertungen!$AS$10,0) -> 0
A32: gesamtes Portfolio | B32: Die Texte sind für Lesende verständlich und nachvollziehbar geschrieben. | C32: =OFFSET(Bewertungen!N26,Bewertungen!$AS$10,0) -> 0
B33: Intertextualität ist im Text transparent und nachvollziehbar formuliert. D. h. es ist durchgängig klar/eindeutig zuzuordnen, wer „spricht“, d.h. wessen Position/Meinung/ Beitrag referiert wird bzw. ob der/die Autor*in selbst „spricht“. | C33: =OFFSET(Bewertungen!N27,Bewertungen!$AS$10,0) -> 0
B34: Die verwendete Literatur wird nachvollziehbar und einheitlich zitiert. | C34: =OFFSET(Bewertungen!N28,Bewertungen!$AS$10,0) -> 0
B35: Die Einteilung in Absätze unter stützt das Textverständnis. | C35: =OFFSET(Bewertungen!N29,Bewertungen!$AS$10,0) -> 0
B36: Die Texte sind weitestgehend fehlerfrei in Bezug auf Rechtschreibung, Zeichensetzung und Grammatik. | C36: =OFFSET(Bewertungen!N30,Bewertungen!$AS$10,0) -> 0

Sheet Stud12
A1: Übung | B1: =Uebung!B3 -> 0
A2: Leitung | B2: =Uebung!B4 -> 0
A3: Nummer | B3: =Uebung!B5 -> 0
A5: Nachname | B5: =OFFSET(Bewertungen!$O$7,Bewertungen!$AS$10,0) -> 0
A6: Vorname | B6: =OFFSET(Bewertungen!$O$8,Bewertungen!$AS$10,0) -> 0
A8: Sie können max. 100 Punkte erreichen. Je Kriterium max. 5 Punkte.
A9: Punktwerte bedeuten: | B9: 4–5= vollständig erkennbar
B10: 2–3 = weitgehend erkennbar
B11: 1 = erste Ansätze erkennbar
B12: 0 = nicht erkennbar
B13: Ihre Gesamtpunktzahl: | C13: =OFFSET(Bewertungen!$O$32,Bewertungen!$AS$10,0) -> 0
A15: Artefakt | B15: Kriterien | C15: Punkte
A17: Fragestellung (Artefakt 1a) | B17: Es liegt eine präzise formulierte Fragestellung vor, die sich auf ein konkretes Thema bezieht. | C17: =OFFSET(Bewertungen!O11,Bewertungen!$AS$10,0) -> 0
A18: Reflexionen (Artefakt 1b, 2d, 3 und 4) | B18: Es wird deutlich, dass eine bewusste Beschäftigung mit dem Thema stattgefunden hat. | C18: =OFFSET(Bewertungen!O12,Bewertungen!$AS$10,0) -> 0
B19: Die Ausgangslage der Reflexion wird beschrieben. | C19: =OFFSET(Bewertungen!O13,Bewertungen!$AS$10,0) -> 0
B20: Die beschriebene Ausgangslage wird analysiert. | C20: =OFFSET(Bewertungen!O14,Bewertungen!$AS$10,0) -> 0
B21: Es werden Verbindungen zwischen Lernerfahrungen hergestellt, z. B. zwischen aktuellen und früheren oder zwischen verschiedenen Lernsituationen etc. | C21: =OFFSET(Bewertungen!O15,Bewertungen!$AS$10,0) -> 0
B22: Vorhandene Vorannahmen, Vorurteile und Stereotype etc. werden hinterfragt. | C22: =OFFSET(Bewertungen!O16,Bewertungen!$AS$10,0) -> 0
B23: Es wird deutlich, dass der*die Schreibende zu neuen Erkenntnissen gelangt ist. | C23: =OFFSET(Bewertungen!O17,Bewertungen!$AS$10,0) -> 0
B24: Aus diesen neuen Erkenntnissen werden Implikationen für das zukünftige Denken und Handeln abgeleitet. | C24: =OFFSET(Bewertungen!O18,Bewertungen!$AS$10,0) -> 0
A25: Response Paper (Artefakt 2a-c) | B25: Arbeitet die wesentlichen Thesen des Artikels präzise heraus. | C25: =OFFSET(Bewertungen!O19,Bewertungen!$AS$10,0) -> 0
B26: Belegt die herausgearbeiteten Thesen mit Verweisen auf den Text | C26: =OFFSET(Bewertungen!O20,Bewertungen!$AS$10,0) -> 0
B27: Ordnet die herausgearbeiteten Thesen anhand weiterer Literatur ein. | C27: =OFFSET(Bewertungen!O21,Bewertungen!$AS$10,0) -> 0
B28: Bezieht kontextuelle Informationen zum Text (z. B. Lebensdaten des/der Autor*in, Denkschule, geschichtliche Einordnung, Zielpublikum) in die Einordnung ein. | C28: =OFFSET(Bewertungen!O22,Bewertungen!$AS$10,0) -> 0
B29: Positioniert sich gegenüber der herausgearbeiteten These. | C29: =OFFSET(Bewertungen!O23,Bewertungen!$AS$10,0) -> 0
B30: Begründet diese Stellung mit einer nachvollziehbaren und schlüssigen Argumentation. | C30: =OFFSET(Bewertungen!O24,Bewertungen!$AS$10,0) -> 0
B31: Der sprachliche Ausdruck ist einem wissenschaftlichen Text angemessen. | C31: =OFFSET(Bewertungen!O25,Bewertungen!$AS$10,0) -> 0
A32: gesamtes Portfolio | B32: Die Texte sind für Lesende verständlich und nachvollziehbar geschrieben. | C32: =OFFSET(Bewertungen!O26,Bewertungen!$AS$10,0) -> 0
B33: Intertextualität ist im Text transparent und nachvollziehbar formuliert. D. h. es ist durchgängig klar/eindeutig zuzuordnen, wer „spricht“, d.h. wessen Position/Meinung/ Beitrag referiert wird bzw. ob der/die Autor*in selbst „spricht“. | C33: =OFFSET(Bewertungen!O27,Bewertungen!$AS$10,0) -> 0
B34: Die verwendete Literatur wird nachvollziehbar und einheitlich zitiert. | C34: =OFFSET(Bewertungen!O28,Bewertungen!$AS$10,0) -> 0
B35: Die Einteilung in Absätze unter stützt das Textverständnis. | C35: =OFFSET(Bewertungen!O29,Bewertungen!$AS$10,0) -> 0
B36: Die Texte sind weitestgehend fehlerfrei in Bezug auf Rechtschreibung, Zeichensetzung und Grammatik. | C36: =OFFSET(Bewertungen!O30,Bewertungen!$AS$10,0) -> 0

Sheet Stud13
A1: Übung | B1: =Uebung!B3 -> 0
A2: Leitung | B2: =Uebung!B4 -> 0
A3: Nummer | B3: =Uebung!B5 -> 0
A5: Nachname | B5: =OFFSET(Bewertungen!$P$7,Bewertungen!$AS$10,0) -> 0
A6: Vorname | B6: =OFFSET(Bewertungen!$P$8,Bewertungen!$AS$10,0) -> 0
A8: Sie können max. 100 Punkte erreichen. Je Kriterium max. 5 Punkte.
A9: Punktwerte bedeuten: | B9: 4–5= vollständig erkennbar
B10: 2–3 = weitgehend erkennbar
B11: 1 = erste Ansätze erkennbar
B12: 0 = nicht erkennbar
B13: Ihre Gesamtpunktzahl: | C13: =OFFSET(Bewertungen!$P$32,Bewertungen!$AS$10,0) -> 0
A15: Artefakt | B15: Kriterien | C15: Punkte
A17: Fragestellung (Artefakt 1a) | B17: Es liegt eine präzise formulierte Fragestellung vor, die sich auf ein konkretes Thema bezieht. | C17: =OFFSET(Bewertungen!P11,Bewertungen!$AS$10,0) -> 0
A18: Reflexionen (Artefakt 1b, 2d, 3 und 4) | B18: Es wird deutlich, dass eine bewusste Beschäftigung mit dem Thema stattgefunden hat. | C18: =OFFSET(Bewertungen!P12,Bewertungen!$AS$10,0) -> 0
B19: Die Ausgangslage der Reflexion wird beschrieben. | C19: =OFFSET(Bewertungen!P13,Bewertungen!$AS$10,0) -> 0
B20: Die beschriebene Ausgangslage wird analysiert. | C20: =OFFSET(Bewertungen!P14,Bewertungen!$AS$10,0) -> 0
B21: Es werden Verbindungen zwischen Lernerfahrungen hergestellt, z. B. zwischen aktuellen und früheren oder zwischen verschiedenen Lernsituationen etc. | C21: =OFFSET(Bewertungen!P15,Bewertungen!$AS$10,0) -> 0
B22: Vorhandene Vorannahmen, Vorurteile und Stereotype etc. werden hinterfragt. | C22: =OFFSET(Bewertungen!P16,Bewertungen!$AS$10,0) -> 0
B23: Es wird deutlich, dass der*die Schreibende zu neuen Erkenntnissen gelangt ist. | C23: =OFFSET(Bewertungen!P17,Bewertungen!$AS$10,0) -> 0
B24: Aus diesen neuen Erkenntnissen werden Implikationen für das zukünftige Denken und Handeln abgeleitet. | C24: =OFFSET(Bewertungen!P18,Bewertungen!$AS$10,0) -> 0
A25: Response Paper (Artefakt 2a-c) | B25: Arbeitet die wesentlichen Thesen des Artikels präzise heraus. | C25: =OFFSET(Bewertungen!P19,Bewertungen!$AS$10,0) -> 0
B26: Belegt die herausgearbeiteten Thesen mit Verweisen auf den Text | C26: =OFFSET(Bewertungen!P20,Bewertungen!$AS$10,0) -> 0
B27: Ordnet die herausgearbeiteten Thesen anhand weiterer Literatur ein. | C27: =OFFSET(Bewertungen!P21,Bewertungen!$AS$10,0) -> 0
B28: Bezieht kontextuelle Informationen zum Text (z. B. Lebensdaten des/der Autor*in, Denkschule, geschichtliche Einordnung, Zielpublikum) in die Einordnung ein. | C28: =OFFSET(Bewertungen!P22,Bewertungen!$AS$10,0) -> 0
B29: Positioniert sich gegenüber der herausgearbeiteten These. | C29: =OFFSET(Bewertungen!P23,Bewertungen!$AS$10,0) -> 0
B30: Begründet diese Stellung mit einer nachvollziehbaren und schlüssigen Argumentation. | C30: =OFFSET(Bewertungen!P24,Bewertungen!$AS$10,0) -> 0
B31: Der sprachliche Ausdruck ist einem wissenschaftlichen Text angemessen. | C31: =OFFSET(Bewertungen!P25,Bewertungen!$AS$10,0) -> 0
A32: gesamtes Portfolio | B32: Die Texte sind für Lesende verständlich und nachvollziehbar geschrieben. | C32: =OFFSET(Bewertungen!P26,Bewertungen!$AS$10,0) -> 0
B33: Intertextualität ist im Text transparent und nachvollziehbar formuliert. D. h. es ist durchgängig klar/eindeutig zuzuordnen, wer „spricht“, d.h. wessen Position/Meinung/ Beitrag referiert wird bzw. ob der/die Autor*in selbst „spricht“. | C33: =OFFSET(Bewertungen!P27,Bewertungen!$AS$10,0) -> 0
B34: Die verwendete Literatur wird nachvollziehbar und einheitlich zitiert. | C34: =OFFSET(Bewertungen!P28,Bewertungen!$AS$10,0) -> 0
B35: Die Einteilung in Absätze unter stützt das Textverständnis. | C35: =OFFSET(Bewertungen!P29,Bewertungen!$AS$10,0) -> 0
B36: Die Texte sind weitestgehend fehlerfrei in Bezug auf Rechtschreibung, Zeichensetzung und Grammatik. | C36: =OFFSET(Bewertungen!P30,Bewertungen!$AS$10,0) -> 0

Sheet Stud14
A1: Übung | B1: =Uebung!B3 -> 0
A2: Leitung | B2: =Uebung!B4 -> 0
A3: Nummer | B3: =Uebung!B5 -> 0
A5: Nachname | B5: =OFFSET(Bewertungen!$Q$7,Bewertungen!$AS$10,0) -> 0
A6: Vorname | B6: =OFFSET(Bewertungen!$Q$8,Bewertungen!$AS$10,0) -> 0
A8: Sie können max. 100 Punkte erreichen. Je Kriterium max. 5 Punkte.
A9: Punktwerte bedeuten: | B9: 4–5= vollständig erkennbar
B10: 2–3 = weitgehend erkennbar
B11: 1 = erste Ansätze erkennbar
B12: 0 = nicht erkennbar
B13: Ihre Gesamtpunktzahl: | C13: =OFFSET(Bewertungen!$Q$32,Bewertungen!$AS$10,0) -> 0
A15: Artefakt | B15: Kriterien | C15: Punkte
A17: Fragestellung (Artefakt 1a) | B17: Es liegt eine präzise formulierte Fragestellung vor, die sich auf ein konkretes Thema bezieht. | C17: =OFFSET(Bewertungen!Q11,Bewertungen!$AS$10,0) -> 0
A18: Reflexionen (Artefakt 1b, 2d, 3 und 4) | B18: Es wird deutlich, dass eine bewusste Beschäftigung mit dem Thema stattgefunden hat. | C18: =OFFSET(Bewertungen!Q12,Bewertungen!$AS$10,0) -> 0
B19: Die Ausgangslage der Reflexion wird beschrieben. | C19: =OFFSET(Bewertungen!Q13,Bewertungen!$AS$10,0) -> 0
B20: Die beschriebene Ausgangslage wird analysiert. | C20: =OFFSET(Bewertungen!Q14,Bewertungen!$AS$10,0) -> 0
B21: Es werden Verbindungen zwischen Lernerfahrungen hergestellt, z. B. zwischen aktuellen und früheren oder zwischen verschiedenen Lernsituationen etc. | C21: =OFFSET(Bewertungen!Q15,Bewertungen!$AS$10,0) -> 0
B22: Vorhandene Vorannahmen, Vorurteile und Stereotype etc. werden hinterfragt. | C22: =OFFSET(Bewertungen!Q16,Bewertungen!$AS$10,0) -> 0
B23: Es wird deutlich, dass der*die Schreibende zu neuen Erkenntnissen gelangt ist. | C23: =OFFSET(Bewertungen!Q17,Bewertungen!$AS$10,0) -> 0
B24: Aus diesen neuen Erkenntnissen werden Implikationen für das zukünftige Denken und Handeln abgeleitet. | C24: =OFFSET(Bewertungen!Q18,Bewertungen!$AS$10,0) -> 0
A25: Response Paper (Artefakt 2a-c) | B25: Arbeitet die wesentlichen Thesen des Artikels präzise heraus. | C25: =OFFSET(Bewertungen!Q19,Bewertungen!$AS$10,0) -> 0
B26: Belegt die herausgearbeiteten Thesen mit Verweisen auf den Text | C26: =OFFSET(Bewertungen!Q20,Bewertungen!$AS$10,0) -> 0
