Workbook

Sheet Instructions
A1: Instructions for Using this Excel Spreadsheet
A3: Step 1: Adding Data Related to Your Course
B4: 1) Select the sheet "Course"
B5: 2) Add the Information in the cells highlighted in yellow.
A7: Step 2: Adding Participants
B8: 1) Export the list of participants from myStudy and open the file.
B9: 2) Click on one of the cells in the list and select the entire table. Copy the selected content.
B10: 3) Switch to this file and open the sheet "List of Participants."
B11: 4) Click on the cell in the upper corner on the left side, that is, A1 (cell highlighted in yellow).
B12: 5) Paste copied content.
B13: You should now be able to see the full list of participants. Names of participants will be automatically added to the other sheets.
B14: It is possible to update this list, for example when you add another participant at the end of the add/drop period.
B15: Please note:
B16: • Changes to the list will affect the entire workbook and that all worksheets will be updated automatically. The list can be updated at any time.
B17: • In the sheet "Grades," information in Columns B (first name) and C (last name) will be listed starting Row 2. If you add data manually, please start in B2. (The table generated via myStudy has a header row."
A20: Step 3: Awarding Points
B21: 1) Switch to the sheet "Grading." Names of participants should be have been added automatically.
B22: 2) Award points for artifacts. Please only award full points.
B23: 3) The final score will be calculated automatically; the score will be listed in Line 32.
A25: Step 4: Sharing Grades with Participants
B26: The workbook contains a separate sheet for each participant. It includes 40 sheets in total (Stud1 to Stud40).
B27: Sheets for participants are arranged in the workbook in the same order as in the list of participants. Grading criteria and scores listed on the sheet "Grading" will be added automatically.
B28: To share results with individual participants, you
B29: 1) need to switch on the separate sheet for the participant (Stud1 to Stud40)
B30: 2) need to save the sheet as a PDF. Use the the option "Save as" and select PDF as file type.
B31: You may share results by emailing the PDF to individual participants.
A33: Step 5: Filing Grades for the Course
B34: You may file grades by sharing the workbook with the Examination Office (Prüfungsamt).
A37: Assessment: Adjusting View and Page Layout
B38: To display the grading criteria while adding grades, you may use the split screen function. This option has already been turned on in this file.
B39: In the horizontal scrollbar, you will find a small double line that can be clicked and dragged (see figure below).
B41: #VALUE!

Sheet Course
A1: Please add your name, title of your course, and course number to this sheet.
A3: Instructor
A4: Title
A5: Course Number

Sheet Grading
A1: You can award up to five points per item/criterion. Please only award full points.
B2: 4–5 = criterion fully met | AS2: 10
B3: 2–3 = criterion met for the most part
B4: 1 = criterion met to some extent
B5: 0 = criterion not met
D6: Name (added automatically from the list of participants)
D7: ='List of Participants'!$C$2 -> 0 | E7: ='List of Participants'!$C$3 -> 0 | F7: ='List of Participants'!$C$4 -> 0 | G7: ='List of Participants'!$C$5 -> 0 | H7: ='List of Participants'!$C$6 -> 0 | I7: ='List of Participants'!$C$7 -> 0 | J7: ='List of Participants'!$C$8 -> 0 | K7: ='List of Participants'!$C$9 -> 0 | L7: ='List of Participants'!$C$10 -> 0 | M7: ='List of Participants'!$C$11 -> 0 | N7: ='List of Participants'!$C$12 -> 0 | O7: ='List of Participants'!$C$13 -> 0 | P7: ='List of Participants'!$C$14 -> 0 | Q7: ='List of Participants'!$C$15 -> 0 | R7: ='List of Participants'!$C$16 -> 0 | S7: ='List of Participants'!$C$17 -> 0 | T7: ='List of Participants'!$C$18 -> 0 | U7: ='List of Participants'!$C$19 -> 0 | V7: ='List of Participants'!$C$20 -> 0 | W7: ='List of Participants'!$C$21 -> 0 | X7: ='List of Participants'!$C$22 -> 0 | Y7: ='List of Participants'!$C$23 -> 0 | Z7: ='List of Participants'!$C$24 -> 0 | AA7: ='List of Participants'!$C$25 -> 0 | AB7: ='List of Participants'!$C$26 -> 0 | AC7: ='List of Participants'!$C$27 -> 0 | AD7: ='List of Participants'!$C$28 -> 0 | AE7: ='List of Participants'!$C$29 -> 0 | AF7: ='List of Participants'!$C$30 -> 0 | AG7: ='List of Participants'!$C$31 -> 0 | AH7: ='List of Participants'!$C$32 -> 0 | AI7: ='List of Participants'!$C$33 -> 0 | AJ7: ='List of Participants'!$C$34 -> 0 | AK7: ='List of Participants'!$C$35 -> 0 | AL7: ='List of Participants'!$C$36 -> 0 | AM7: ='List of Participants'!$C$37 -> 0 | AN7: ='List of Participants'!$C$38 -> 0 | AO7: ='List of Participants'!$C$39 -> 0 | AP7: ='List of Participants'!$C$40 -> 0 | AQ7: ='List of Participants'!$C$41 -> 0
D8: ='List of Participants'!$B$2 -> 0 | E8: ='List of Participants'!$B$3 -> 0 | F8: ='List of Participants'!$B$4 -> 0 | G8: ='List of Participants'!$B$5 -> 0 | H8: ='List of Participants'!$B$6 -> 0 | I8: ='List of Participants'!$B$7 -> 0 | J8: ='List of Participants'!$B$8 -> 0 | K8: ='List of Participants'!$B$9 -> 0 | L8: ='List of Participants'!$B$10 -> 0 | M8: ='List of Participants'!$B$11 -> 0 | N8: ='List of Participants'!$B$12 -> 0 | O8: ='List of Participants'!$B$13 -> 0 | P8: ='List of Participants'!$B$14 -> 0 | Q8: ='List of Participants'!$B$15 -> 0 | R8: ='List of Participants'!$B$16 -> 0 | S8: ='List of Participants'!$B$17 -> 0 | T8: ='List of Participants'!$B$18 -> 0 | U8: ='List of Participants'!$B$19 -> 0 | V8: ='List of Participants'!$B$20 -> 0 | W8: ='List of Participants'!$B$21 -> 0 | X8: ='List of Participants'!$B$22 -> 0 | Y8: ='List of Participants'!$B$23 -> 0 | Z8: ='List of Participants'!$B$24 -> 0 | AA8: ='List of Participants'!$B$25 -> 0 | AB8: ='List of Participants'!$B$26 -> 0 | AC8: ='List of Participants'!$B$27 -> 0 | AD8: ='List of Participants'!$B$28 -> 0 | AE8: ='List of Participants'!$B$29 -> 0 | AF8: ='List of Participants'!$B$30 -> 0 | AG8: ='List of Participants'!$B$31 -> 0 | AH8: ='List of Participants'!$B$32 -> 0 | AI8: ='List of Participants'!$B$33 -> 0 | AJ8: ='List of Participants'!$B$34 -> 0 | AK8: ='List of Participants'!$B$35 -> 0 | AL8: ='List of Participants'!$B$36 -> 0 | AM8: ='List of Participants'!$B$37 -> 0 | AN8: ='List of Participants'!$B$38 -> 0 | AO8: ='List of Participants'!$B$39 -> 0 | AP8: ='List of Participants'!$B$40 -> 0 | AQ8: ='List of Participants'!$B$41 -> 0
A9: Artefact | B9: Items
A11: Research Question (Artefact 1a) | B11: The research question is precise and related to a specific topic.
A12: Reflections (Artefacts 1b, 2d, 3, and 4) | B12: The writer has carefully considered and deepy engaged with the topic of the respective task.
B13: The writer has identified and described one specific situation in the respective reflection.
B14: The writer has analyzed this specific situation.
B15: The writer relates different learning experiences, for example the current experience to an earlier one.
B16: The writer questions previously held assumptions, biases, or stereotypes.
B17: The writer has gained valuable new insignts.
B18: Based on these insights, the writer discusses implications for future actions, thinking, and learning.
A19: Response Paper (Artefact 2a-c) | B19: The writer identifies the main thesis and key arguments of the text.
B20: The writer elaborates on these main points and provides references to the text.
B21: The writer contextualizes these points by also drawing on high-quality sources.
B22: The writer considers relevant contextual information, for example historical context, audience, or intellectual tradition.
B23: The writer positions themselves vis-a-vis the text and, perhaps, in the debate to which the text contributes.
B24: The writer supports this position with reasonable arguments.
B25: The writer's diction, tone, and style is appropriate for an academic audience.
A26: Entire Portfolio | B26: It is easy to read the text and to understand the writer's reasoning and position.
B27: The writer has carefully marked references to other texts as such and clearly attributed ideas to others. It is always obvious who is "speaking" and whose positions--the writer's, those of others--are discussed in the artifact.
B28: References to other sources are formatted correctly and consistently; full bibliographic information is provided in the list of works cited.
B29: The writer has structured the content and organized paragraphs in line with readers' expectations.
B30: In terms of grammar, spelling, and punctuation, the portfolio contains 5 = no or very few errors 4 = some errors 3 = several errors. It is possible for readers to follow the writer's explanations without any effort. 2 = many errors, some of them obvious mistakes. It is, at times, difficult for readers to understand what the writer wants to say. 1 = many errors, some of them obvious mistakes. It is very difficult for readers to understand the writer's explanations. 0 = many errors, many of them obvious mistakes. It is impossible for readers to understand what the writer wants to say.
B32: Total Score | D32: =SUM(D11:D30) -> 0 | E32: =SUM(E11:E30) -> 0 | F32: =SUM(F11:F30) -> 0 | G32: =SUM(G11:G30) -> 0 | H32: =SUM(H11:H30) -> 0 | I32: =SUM(I11:I30) -> 0 | J32: =SUM(J11:J30) -> 0 | K32: =SUM(K11:K30) -> 0 | ... AQ32: =SUM(AQ11:AQ30) -> 0

Sheet List of Participants

Sheet Stud1
A1: Instructor | B1: =Course!B3 -> 0
A2: Title | B2: =Course!B4 -> 0
A3: Course Number | B3: =Course!B5 -> 0
A5: Last Name | B5: =OFFSET(Grading!D7, Grading!$AS$10,0) -> 0
A6: First Name | B6: =OFFSET(Grading!D8, Grading!$AS$10,0) -> 0
A8: Grading Rubric
A9: max. total points per item: 5
A10: max. total points: 100
B11: 4–5 = criterion fully met
B12: 2–3 = criterion met for the most part
B13: 1 = criterion met to some extent
B14: 0 = criterion not met
B15: Total Score | C15: =OFFSET(Grading!D32, Grading!$AS$10,0) -> 0
A17: Artefact | B17: Items | C17: Points
A19: Research Question (Artefact 1a) | B19: The research question is precise and related to a specific topic. | C19: =OFFSET(Grading!D11, Grading!$AS$10,0) -> 0
A20: Reflections (Artefacts 1b, 2d, 3, and 4) | B20: The writer has carefully considered and deepy engaged with the topic. | C20: =OFFSET(Grading!D12, Grading!$AS$10,0) -> 0
B21: The writer has identified and described one specific situation. | C21: =OFFSET(Grading!D13, Grading!$AS$10,0) -> 0
B22: The writer has analyzed this specific situation. | C22: =OFFSET(Grading!D14, Grading!$AS$10,0) -> 0
B23: The writer relates different learning experiences, for example the current experience to an earlier one. | C23: =OFFSET(Grading!D15, Grading!$AS$10,0) -> 0
B24: The writer questions previously held assumptions, biases, or stereotypes. | C24: =OFFSET(Grading!D16, Grading!$AS$10,0) -> 0
B25: The writer has gained valuable new insignts. | C25: =OFFSET(Grading!D17, Grading!$AS$10,0) -> 0
B26: Based on these insights, the writer discusses implications for future actions, thinking, and learning. | C26: =OFFSET(Grading!D18, Grading!$AS$10,0) -> 0
A27: Response Paper (Artefact 2a-c) | B27: The writer identifies the main thesis and key arguments of the text. | C27: =OFFSET(Grading!D19, Grading!$AS$10,0) -> 0
B28: The writer elaborates on these main points and provides references to the text. | C28: =OFFSET(Grading!D20, Grading!$AS$10,0) -> 0
B29: The writer contextualizes these points by also drawing on high-quality sources. | C29: =OFFSET(Grading!D21, Grading!$AS$10,0) -> 0
B30: The writer considers relevant contextual information, for example historical context, audience, or intellectual tradition. | C30: =OFFSET(Grading!D22, Grading!$AS$10,0) -> 0
B31: The writer positions themselves vis-a-vis the text and, perhaps, in the debate to which the text contributes. | C31: =OFFSET(Grading!D23, Grading!$AS$10,0) -> 0
B32: The writer supports this position with reasonable arguments. | C32: =OFFSET(Grading!D24, Grading!$AS$10,0) -> 0
B33: The writer's diction, tone, and style is appropriate for an academic audience. | C33: =OFFSET(Grading!D25, Grading!$AS$10,0) -> 0
A34: Entire Portfolio | B34: It is easy to read the text and to understand the writer's reasoning and position. | C34: =OFFSET(Grading!D26, Grading!$AS$10,0) -> 0
B35: The writer has carefully marked references to other texts as such and clearly attributed ideas to others. It is always obvious who is "speaking" and whose positions--the writer's, those of others--are discussed in the artifact. | C35: =OFFSET(Grading!D27, Grading!$AS$10,0) -> 0
B36: References to other sources are formatted correctly and consistently; full bibliographic information is provided in the list of works cited. | C36: =OFFSET(Grading!D28, Grading!$AS$10,0) -> 0
B37: The writer has structured the content and organized paragraphs in line with readers' expectations. | C37: =OFFSET(Grading!D29, Grading!$AS$10,0) -> 0
B38: The texts are mostly correct in terms of spelling, punctuation, and grammar. | C38: =OFFSET(Grading!D30, Grading!$AS$10,0) -> 0

Sheet Stud2
A1: Instructor | B1: =Course!B3 -> 0
A2: Title | B2: =Course!B4 -> 0
A3: Course Number | B3: =Course!B5 -> 0
A5: Last Name | B5: =OFFSET(Grading!E7, Grading!$AS$10,0) -> 0
A6: First Name | B6: =OFFSET(Grading!E8, Grading!$AS$10,0) -> 0
A8: Grading Rubric
A9: max. total points per item: 5
A10: max. total points: 100
B11: 4–5 = criterion fully met
B12: 2–3 = criterion met for the most part
B13: 1 = criterion met to some extent
B14: 0 = criterion not met
B15: Total Score | C15: =OFFSET(Grading!E32, Grading!$AS$10,0) -> 0
A17: Artefact | B17: Items | C17: Points
A19: Research Question (Artefact 1a) | B19: The research question is precise and related to a specific topic. | C19: =OFFSET(Grading!E11, Grading!$AS$10,0) -> 0
A20: Reflections (Artefacts 1b, 2d, 3, and 4) | B20: The writer has carefully considered and deepy engaged with the topic. | C20: =OFFSET(Grading!E12, Grading!$AS$10,0) -> 0
B21: The writer has identified and described one specific situation. | C21: =OFFSET(Grading!E13, Grading!$AS$10,0) -> 0
B22: The writer has analyzed this specific situation. | C22: =OFFSET(Grading!E14, Grading!$AS$10,0) -> 0
B23: The writer relates different learning experiences, for example the current experience to an earlier one. | C23: =OFFSET(Grading!E15, Grading!$AS$10,0) -> 0
B24: The writer questions previously held assumptions, biases, or stereotypes. | C24: =OFFSET(Grading!E16, Grading!$AS$10,0) -> 0
B25: The writer has gained valuable new insignts. | C25: =OFFSET(Grading!E17, Grading!$AS$10,0) -> 0
B26: Based on these insights, the writer discusses implications for future actions, thinking, and learning. | C26: =OFFSET(Grading!E18, Grading!$AS$10,0) -> 0
A27: Response Paper (Artefact 2a-c) | B27: The writer identifies the main thesis and key arguments of the text. | C27: =OFFSET(Grading!E19, Grading!$AS$10,0) -> 0
B28: The writer elaborates on these main points and provides references to the text. | C28: =OFFSET(Grading!E20, Grading!$AS$10,0) -> 0
B29: The writer contextualizes these points by also drawing on high-quality sources. | C29: =OFFSET(Grading!E21, Grading!$AS$10,0) -> 0
B30: The writer considers relevant contextual information, for example historical context, audience, or intellectual tradition. | C30: =OFFSET(Grading!E22, Grading!$AS$10,0) -> 0
B31: The writer positions themselves vis-a-vis the text and, perhaps, in the debate to which the text contributes. | C31: =OFFSET(Grading!E23, Grading!$AS$10,0) -> 0
B32: The writer supports this position with reasonable arguments. | C32: =OFFSET(Grading!E24, Grading!$AS$10,0) -> 0
B33: The writer's diction, tone, and style is appropriate for an academic audience. | C33: =OFFSET(Grading!E25, Grading!$AS$10,0) -> 0
A34: Entire Portfolio | B34: It is easy to read the text and to understand the writer's reasoning and position. | C34: =OFFSET(Grading!E26, Grading!$AS$10,0) -> 0
B35: The writer has carefully marked references to other texts as such and clearly attributed ideas to others. It is always obvious who is "speaking" and whose positions--the writer's, those of others--are discussed in the artifact. | C35: =OFFSET(Grading!E27, Grading!$AS$10,0) -> 0
B36: References to other sources are formatted correctly and consistently; full bibliographic information is provided in the list of works cited. | C36: =OFFSET(Grading!E28, Grading!$AS$10,0) -> 0
B37: The writer has structured the content and organized paragraphs in line with readers' expectations. | C37: =OFFSET(Grading!E29, Grading!$AS$10,0) -> 0
B38: The texts are mostly correct in terms of spelling, punctuation, and grammar. | C38: =OFFSET(Grading!E30, Grading!$AS$10,0) -> 0

Sheet Stud3
A1: Instructor | B1: =Course!B3 -> 0
A2: Title | B2: =Course!B4 -> 0
A3: Course Number | B3: =Course!B5 -> 0
A5: Last Name | B5: =OFFSET(Grading!F7, Grading!$AS$10,0) -> 0
A6: First Name | B6: =OFFSET(Grading!F8, Grading!$AS$10,0) -> 0
A8: Grading Rubric
A9: max. total points per item: 5
A10: max. total points: 100
B11: 4–5 = criterion fully met
B12: 2–3 = criterion met for the most part
B13: 1 = criterion met to some extent
B14: 0 = criterion not met
B15: Total Score | C15: =OFFSET(Grading!F32, Grading!$AS$10,0) -> 0
A17: Artefact | B17: Items | C17: Points
A19: Research Question (Artefact 1a) | B19: The research question is precise and related to a specific topic. | C19: =OFFSET(Grading!F11, Grading!$AS$10,0) -> 0
A20: Reflections (Artefacts 1b, 2d, 3, and 4) | B20: The writer has carefully considered and deepy engaged with the topic. | C20: =OFFSET(Grading!F12, Grading!$AS$10,0) -> 0
B21: The writer has identified and described one specific situation. | C21: =OFFSET(Grading!F13, Grading!$AS$10,0) -> 0
B22: The writer has analyzed this specific situation. | C22: =OFFSET(Grading!F14, Grading!$AS$10,0) -> 0
B23: The writer relates different learning experiences, for example the current experience to an earlier one. | C23: =OFFSET(Grading!F15, Grading!$AS$10,0) -> 0
B24: The writer questions previously held assumptions, biases, or stereotypes. | C24: =OFFSET(Grading!F16, Grading!$AS$10,0) -> 0
B25: The writer has gained valuable new insignts. | C25: =OFFSET(Grading!F17, Grading!$AS$10,0) -> 0
B26: Based on these insights, the writer discusses implications for future actions, thinking, and learning. | C26: =OFFSET(Grading!F18, Grading!$AS$10,0) -> 0
A27: Response Paper (Artefact 2a-c) | B27: The writer identifies the main thesis and key arguments of the text. | C27: =OFFSET(Grading!F19, Grading!$AS$10,0) -> 0
B28: The writer elaborates on these main points and provides references to the text. | C28: =OFFSET(Grading!F20, Grading!$AS$10,0) -> 0
B29: The writer contextualizes these points by also drawing on high-quality sources. | C29: =OFFSET(Grading!F21, Grading!$AS$10,0) -> 0
B30: The writer considers relevant contextual information, for example historical context, audience, or intellectual tradition. | C30: =OFFSET(Grading!F22, Grading!$AS$10,0) -> 0
B31: The writer positions themselves vis-a-vis the text and, perhaps, in the debate to which the text contributes. | C31: =OFFSET(Grading!F23, Grading!$AS$10,0) -> 0
B32: The writer supports this position with reasonable arguments. | C32: =OFFSET(Grading!F24, Grading!$AS$10,0) -> 0
B33: The writer's diction, tone, and style is appropriate for an academic audience. | C33: =OFFSET(Grading!F25, Grading!$AS$10,0) -> 0
A34: Entire Portfolio | B34: It is easy to read the text and to understand the writer's reasoning and position. | C34: =OFFSET(Grading!F26, Grading!$AS$10,0) -> 0
B35: The writer has carefully marked references to other texts as such and clearly attributed ideas to others. It is always obvious who is "speaking" and whose positions--the writer's, those of others--are discussed in the artifact. | C35: =OFFSET(Grading!F27, Grading!$AS$10,0) -> 0
B36: References to other sources are formatted correctly and consistently; full bibliographic information is provided in the list of works cited. | C36: =OFFSET(Grading!F28, Grading!$AS$10,0) -> 0
B37: The writer has structured the content and organized paragraphs in line with readers' expectations. | C37: =OFFSET(Grading!F29, Grading!$AS$10,0) -> 0
B38: The texts are mostly correct in terms of spelling, punctuation, and grammar. | C38: =OFFSET(Grading!F30, Grading!$AS$10,0) -> 0

Sheet Stud4
A1: Instructor | B1: =Course!B3 -> 0
A2: Title | B2: =Course!B4 -> 0
A3: Course Number | B3: =Course!B5 -> 0
A5: Last Name | B5: =OFFSET(Grading!G7, Grading!$AS$10,0) -> 0
A6: First Name | B6: =OFFSET(Grading!G8, Grading!$AS$10,0) -> 0
A8: Grading Rubric
A9: max. total points per item: 5
A10: max. total points: 100
B11: 4–5 = criterion fully met
B12: 2–3 = criterion met for the most part
B13: 1 = criterion met to some extent
B14: 0 = criterion not met
B15: Total Score | C15: =OFFSET(Grading!G32, Grading!$AS$10,0) -> 0
A17: Artefact | B17: Items | C17: Points
A19: Research Question (Artefact 1a) | B19: The research question is precise and related to a specific topic. | C19: =OFFSET(Grading!G11, Grading!$AS$10,0) -> 0
A20: Reflections (Artefacts 1b, 2d, 3, and 4) | B20: The writer has carefully considered and deepy engaged with the topic. | C20: =OFFSET(Grading!G12, Grading!$AS$10,0) -> 0
B21: The writer has identified and described one specific situation. | C21: =OFFSET(Grading!G13, Grading!$AS$10,0) -> 0
B22: The writer has analyzed this specific situation. | C22: =OFFSET(Grading!G14, Grading!$AS$10,0) -> 0
B23: The writer relates different learning experiences, for example the current experience to an earlier one. | C23: =OFFSET(Grading!G15, Grading!$AS$10,0) -> 0
B24: The writer questions previously held assumptions, biases, or stereotypes. | C24: =OFFSET(Grading!G16, Grading!$AS$10,0) -> 0
B25: The writer has gained valuable new insignts. | C25: =OFFSET(Grading!G17, Grading!$AS$10,0) -> 0
B26: Based on these insights, the writer discusses implications for future actions, thinking, and learning. | C26: =OFFSET(Grading!G18, Grading!$AS$10,0) -> 0
A27: Response Paper (Artefact 2a-c) | B27: The writer identifies the main thesis and key arguments of the text. | C27: =OFFSET(Grading!G19, Grading!$AS$10,0) -> 0
B28: The writer elaborates on these main points and provides references to the text. | C28: =OFFSET(Grading!G20, Grading!$AS$10,0) -> 0
B29: The writer contextualizes these points by also drawing on high-quality sources. | C29: =OFFSET(Grading!G21, Grading!$AS$10,0) -> 0
B30: The writer considers relevant contextual information, for example historical context, audience, or intellectual tradition. | C30: =OFFSET(Grading!G22, Grading!$AS$10,0) -> 0
B31: The writer positions themselves vis-a-vis the text and, perhaps, in the debate to which the text contributes. | C31: =OFFSET(Grading!G23, Grading!$AS$10,0) -> 0
B32: The writer supports this position with reasonable arguments. | C32: =OFFSET(Grading!G24, Grading!$AS$10,0) -> 0
B33: The writer's diction, tone, and style is appropriate for an academic audience. | C33: =OFFSET(Grading!G25, Grading!$AS$10,0) -> 0
A34: Entire Portfolio | B34: It is easy to read the text and to understand the writer's reasoning and position. | C34: =OFFSET(Grading!G26, Grading!$AS$10,0) -> 0
B35: The writer has carefully marked references to other texts as such and clearly attributed ideas to others. It is always obvious who is "speaking" and whose positions--the writer's, those of others--are discussed in the artifact. | C35: =OFFSET(Grading!G27, Grading!$AS$10,0) -> 0
B36: References to other sources are formatted correctly and consistently; full bibliographic information is provided in the list of works cited. | C36: =OFFSET(Grading!G28, Grading!$AS$10,0) -> 0
B37: The writer has structured the content and organized paragraphs in line with readers' expectations. | C37: =OFFSET(Grading!G29, Grading!$AS$10,0) -> 0
B38: The texts are mostly correct in terms of spelling, punctuation, and grammar. | C38: =OFFSET(Grading!G30, Grading!$AS$10,0) -> 0

Sheet Stud5
A1: Instructor | B1: =Course!B3 -> 0
A2: Title | B2: =Course!B4 -> 0
A3: Course Number | B3: =Course!B5 -> 0
A5: Last Name | B5: =OFFSET(Grading!H7, Grading!$AS$10,0) -> 0
A6: First Name | B6: =OFFSET(Grading!H8, Grading!$AS$10,0) -> 0
A8: Grading Rubric
A9: max. total points per item: 5
A10: max. total points: 100
B11: 4–5 = criterion fully met
B12: 2–3 = criterion met for the most part
B13: 1 = criterion met to some extent
B14: 0 = criterion not met
B15: Total Score | C15: =OFFSET(Grading!H32, Grading!$AS$10,0) -> 0
A17: Artefact | B17: Items | C17: Points
A19: Research Question (Artefact 1a) | B19: The research question is precise and related to a specific topic. | C19: =OFFSET(Grading!H11, Grading!$AS$10,0) -> 0
A20: Reflections (Artefacts 1b, 2d, 3, and 4) | B20: The writer has carefully considered and deepy engaged with the topic. | C20: =OFFSET(Grading!H12, Grading!$AS$10,0) -> 0
B21: The writer has identified and described one specific situation. | C21: =OFFSET(Grading!H13, Grading!$AS$10,0) -> 0
B22: The writer has analyzed this specific situation. | C22: =OFFSET(Grading!H14, Grading!$AS$10,0) -> 0
B23: The writer relates different learning experiences, for example the current experience to an earlier one. | C23: =OFFSET(Grading!H15, Grading!$AS$10,0) -> 0
B24: The writer questions previously held assumptions, biases, or stereotypes. | C24: =OFFSET(Grading!H16, Grading!$AS$10,0) -> 0
B25: The writer has gained valuable new insignts. | C25: =OFFSET(Grading!H17, Grading!$AS$10,0) -> 0
B26: Based on these insights, the writer discusses implications for future actions, thinking, and learning. | C26: =OFFSET(Grading!H18, Grading!$AS$10,0) -> 0
A27: Response Paper (Artefact 2a-c) | B27: The writer identifies the main thesis and key arguments of the text. | C27: =OFFSET(Grading!H19, Grading!$AS$10,0) -> 0
B28: The writer elaborates on these main points and provides references to the text. | C28: =OFFSET(Grading!H20, Grading!$AS$10,0) -> 0
B29: The writer contextualizes these points by also drawing on high-quality sources. | C29: =OFFSET(Grading!H21, Grading!$AS$10,0) -> 0
B30: The writer considers relevant contextual information, for example historical context, audience, or intellectual tradition. | C30: =OFFSET(Grading!H22, Grading!$AS$10,0) -> 0
B31: The writer positions themselves vis-a-vis the text and, perhaps, in the debate to which the text contributes. | C31: =OFFSET(Grading!H23, Grading!$AS$10,0) -> 0
B32: The writer supports this position with reasonable arguments. | C32: =OFFSET(Grading!H24, Grading!$AS$10,0) -> 0
B33: The writer's diction, tone, and style is appropriate for an academic audience. | C33: =OFFSET(Grading!H25, Grading!$AS$10,0) -> 0
A34: Entire Portfolio | B34: It is easy to read the text and to understand the writer's reasoning and position. | C34: =OFFSET(Grading!H26, Grading!$AS$10,0) -> 0
B35: The writer has carefully marked references to other texts as such and clearly attributed ideas to others. It is always obvious who is "speaking" and whose positions--the writer's, those of others--are discussed in the artifact. | C35: =OFFSET(Grading!H27, Grading!$AS$10,0) -> 0
B36: References to other sources are formatted correctly and consistently; full bibliographic information is provided in the list of works cited. | C36: =OFFSET(Grading!H28, Grading!$AS$10,0) -> 0
B37: The writer has structured the content and organized paragraphs in line with readers' expectations. | C37: =OFFSET(Grading!H29, Grading!$AS$10,0) -> 0
B38: The texts are mostly correct in terms of spelling, punctuation, and grammar. | C38: =OFFSET(Grading!H30, Grading!$AS$10,0) -> 0

Sheet Stud6
A1: Instructor | B1: =Course!B3 -> 0
A2: Title | B2: =Course!B4 -> 0
A3: Course Number | B3: =Course!B5 -> 0
A5: Last Name | B5: =OFFSET(Grading!I7, Grading!$AS$10,0) -> 0
A6: First Name | B6: =OFFSET(Grading!I8, Grading!$AS$10,0) -> 0
A8: Grading Rubric
A9: max. total points per item: 5
A10: max. total points: 100
B11: 4–5 = criterion fully met
B12: 2–3 = criterion met for the most part
B13: 1 = criterion met to some extent
B14: 0 = criterion not met
B15: Total Score | C15: =OFFSET(Grading!I32, Grading!$AS$10,0) -> 0
A17: Artefact | B17: Items | C17: Points
A19: Research Question (Artefact 1a) | B19: The research question is precise and related to a specific topic. | C19: =OFFSET(Grading!I11, Grading!$AS$10,0) -> 0
A20: Reflections (Artefacts 1b, 2d, 3, and 4) | B20: The writer has carefully considered and deepy engaged with the topic. | C20: =OFFSET(Grading!I12, Grading!$AS$10,0) -> 0
B21: The writer has identified and described one specific situation. | C21: =OFFSET(Grading!I13, Grading!$AS$10,0) -> 0
B22: The writer has analyzed this specific situation. | C22: =OFFSET(Grading!I14, Grading!$AS$10,0) -> 0
B23: The writer relates different learning experiences, for example the current experience to an earlier one. | C23: =OFFSET(Grading!I15, Grading!$AS$10,0) -> 0
B24: The writer questions previously held assumptions, biases, or stereotypes. | C24: =OFFSET(Grading!I16, Grading!$AS$10,0) -> 0
B25: The writer has gained valuable new insignts. | C25: =OFFSET(Grading!I17, Grading!$AS$10,0) -> 0
B26: Based on these insights, the writer discusses implications for future actions, thinking, and learning. | C26: =OFFSET(Grading!I18, Grading!$AS$10,0) -> 0
A27: Response Paper (Artefact 2a-c) | B27: The writer identifies the main thesis and key arguments of the text. | C27: =OFFSET(Grading!I19, Grading!$AS$10,0) -> 0
B28: The writer elaborates on these main points and provides references to the text. | C28: =OFFSET(Grading!I20, Grading!$AS$10,0) -> 0
B29: The writer contextualizes these points by also drawing on high-quality sources. | C29: =OFFSET(Grading!I21, Grading!$AS$10,0) -> 0
B30: The writer considers relevant contextual information, for example historical context, audience, or intellectual tradition. | C30: =OFFSET(Grading!I22, Grading!$AS$10,0) -> 0
B31: The writer positions themselves vis-a-vis the text and, perhaps, in the debate to which the text contributes. | C31: =OFFSET(Grading!I23, Grading!$AS$10,0) -> 0
B32: The writer supports this position with reasonable arguments. | C32: =OFFSET(Grading!I24, Grading!$AS$10,0) -> 0
B33: The writer's diction, tone, and style is appropriate for an academic audience. | C33: =OFFSET(Grading!I25, Grading!$AS$10,0) -> 0
A34: Entire Portfolio | B34: It is easy to read the text and to understand the writer's reasoning and position. | C34: =OFFSET(Grading!I26, Grading!$AS$10,0) -> 0
B35: The writer has carefully marked references to other texts as such and clearly attributed ideas to others. It is always obvious who is "speaking" and whose positions--the writer's, those of others--are discussed in the artifact. | C35: =OFFSET(Grading!I27, Grading!$AS$10,0) -> 0
B36: References to other sources are formatted correctly and consistently; full bibliographic information is provided in the list of works cited. | C36: =OFFSET(Grading!I28, Grading!$AS$10,0) -> 0
B37: The writer has structured the content and organized paragraphs in line with readers' expectations. | C37: =OFFSET(Grading!I29, Grading!$AS$10,0) -> 0
B38: The texts are mostly correct in terms of spelling, punctuation, and grammar. | C38: =OFFSET(Grading!I30, Grading!$AS$10,0) -> 0

Sheet Stud7
A1: Instructor | B1: =Course!B3 -> 0
A2: Title | B2: =Course!B4 -> 0
A3: Course Number | B3: =Course!B5 -> 0
A5: Last Name | B5: =OFFSET(Grading!J7, Grading!$AS$10,0) -> 0
A6: First Name | B6: =OFFSET(Grading!J8, Grading!$AS$10,0) -> 0
A8: Grading Rubric
A9: max. total points per item: 5
A10: max. total points: 100
B11: 4–5 = criterion fully met
B12: 2–3 = criterion met for the most part
B13: 1 = criterion met to some extent
B14: 0 = criterion not met
B15: Total Score | C15: =OFFSET(Grading!J32, Grading!$AS$10,0) -> 0
A17: Artefact | B17: Items | C17: Points
A19: Research Question (Artefact 1a) | B19: The research question is precise and related to a specific topic. | C19: =OFFSET(Grading!J11, Grading!$AS$10,0) -> 0
A20: Reflections (Artefacts 1b, 2d, 3, and 4) | B20: The writer has carefully considered and deepy engaged with the topic. | C20: =OFFSET(Grading!J12, Grading!$AS$10,0) -> 0
B21: The writer has identified and described one specific situation. | C21: =OFFSET(Grading!J13, Grading!$AS$10,0) -> 0
B22: The writer has analyzed this specific situation. | C22: =OFFSET(Grading!J14, Grading!$AS$10,0) -> 0
B23: The writer relates different learning experiences, for example the current experience to an earlier one. | C23: =OFFSET(Grading!J15, Grading!$AS$10,0) -> 0
B24: The writer questions previously held assumptions, biases, or stereotypes. | C24: =OFFSET(Grading!J16, Grading!$AS$10,0) -> 0
B25: The writer has gained valuable new insignts. | C25: =OFFSET(Grading!J17, Grading!$AS$10,0) -> 0
B26: Based on these insights, the writer discusses implications for future actions, thinking, and learning. | C26: =OFFSET(Grading!J18, Grading!$AS$10,0) -> 0
A27: Response Paper (Artefact 2a-c) | B27: The writer identifies the main thesis and key arguments of the text. | C27: =OFFSET(Grading!J19, Grading!$AS$10,0) -> 0
B28: The writer elaborates on these main points and provides references to the text. | C28: =OFFSET(Grading!J20, Grading!$AS$10,0) -> 0
B29: The writer contextualizes these points by also drawing on high-quality sources. | C29: =OFFSET(Grading!J21, Grading!$AS$10,0) -> 0
B30: The writer considers relevant contextual information, for example historical context, audience, or intellectual tradition. | C30: =OFFSET(Grading!J22, Grading!$AS$10,0) -> 0
B31: The writer positions themselves vis-a-vis the text and, perhaps, in the debate to which the text contributes. | C31: =OFFSET(Grading!J23, Grading!$AS$10,0) -> 0
B32: The writer supports this position with reasonable arguments. | C32: =OFFSET(Grading!J24, Grading!$AS$10,0) -> 0
B33: The writer's diction, tone, and style is appropriate for an academic audience. | C33: =OFFSET(Grading!J25, Grading!$AS$10,0) -> 0
A34: Entire Portfolio | B34: It is easy to read the text and to understand the writer's reasoning and position. | C34: =OFFSET(Grading!J26, Grading!$AS$10,0) -> 0
B35: The writer has carefully marked references to other texts as such and clearly attributed ideas to others. It is always obvious who is "speaking" and whose positions--the writer's, those of others--are discussed in the artifact. | C35: =OFFSET(Grading!J27, Grading!$AS$10,0) -> 0
B36: References to other sources are formatted correctly and consistently; full bibliographic information is provided in the list of works cited. | C36: =OFFSET(Grading!J28, Grading!$AS$10,0) -> 0
B37: The writer has structured the content and organized paragraphs in line with readers' expectations. | C37: =OFFSET(Grading!J29, Grading!$AS$10,0) -> 0
B38: The texts are mostly correct in terms of spelling, punctuation, and grammar. | C38: =OFFSET(Grading!J30, Grading!$AS$10,0) -> 0

Sheet Stud8
A1: Instructor | B1: =Course!B3 -> 0
A2: Title | B2: =Course!B4 -> 0
A3: Course Number | B3: =Course!B5 -> 0
A5: Last Name | B5: =OFFSET(Grading!K7, Grading!$AS$10,0) -> 0
A6: First Name | B6: =OFFSET(Grading!K8, Grading!$AS$10,0) -> 0
A8: Grading Rubric
A9: max. total points per item: 5
A10: max. total points: 100
B11: 4–5 = criterion fully met
B12: 2–3 = criterion met for the most part
B13: 1 = criterion met to some extent
B14: 0 = criterion not met
B15: Total Score | C15: =OFFSET(Grading!K32, Grading!$AS$10,0) -> 0
A17: Artefact | B17: Items | C17: Points
A19: Research Question (Artefact 1a) | B19: The research question is precise and related to a specific topic. | C19: =OFFSET(Grading!K11, Grading!$AS$10,0) -> 0
A20: Reflections (Artefacts 1b, 2d, 3, and 4) | B20: The writer has carefully considered and deepy engaged with the topic. | C20: =OFFSET(Grading!K12, Grading!$AS$10,0) -> 0
B21: The writer has identified and described one specific situation. | C21: =OFFSET(Grading!K13, Grading!$AS$10,0) -> 0
B22: The writer has analyzed this specific situation. | C22: =OFFSET(Grading!K14, Grading!$AS$10,0) -> 0
B23: The writer relates different learning experiences, for example the current experience to an earlier one. | C23: =OFFSET(Grading!K15, Grading!$AS$10,0) -> 0
B24: The writer questions previously held assumptions, biases, or stereotypes. | C24: =OFFSET(Grading!K16, Grading!$AS$10,0) -> 0
B25: The writer has gained valuable new insignts. | C25: =OFFSET(Grading!K17, Grading!$AS$10,0) -> 0
B26: Based on these insights, the writer discusses implications for future actions, thinking, and learning. | C26: =OFFSET(Grading!K18, Grading!$AS$10,0) -> 0
A27: Response Paper (Artefact 2a-c) | B27: The writer identifies the main thesis and key arguments of the text. | C27: =OFFSET(Grading!K19, Grading!$AS$10,0) -> 0
B28: The writer elaborates on these main points and provides references to the text. | C28: =OFFSET(Grading!K20, Grading!$AS$10,0) -> 0
B29: The writer contextualizes these points by also drawing on high-quality sources. | C29: =OFFSET(Grading!K21, Grading!$AS$10,0) -> 0
B30: The writer considers relevant contextual information, for example historical context, audience, or intellectual tradition. | C30: =OFFSET(Grading!K22, Grading!$AS$10,0) -> 0
B31: The writer positions themselves vis-a-vis the text and, perhaps, in the debate to which the text contributes. | C31: =OFFSET(Grading!K23, Grading!$AS$10,0) -> 0
B32: The writer supports this position with reasonable arguments. | C32: =OFFSET(Grading!K24, Grading!$AS$10,0) -> 0
B33: The writer's diction, tone, and style is appropriate for an academic audience. | C33: =OFFSET(Grading!K25, Grading!$AS$10,0) -> 0
A34: Entire Portfolio | B34: It is easy to read the text and to understand the writer's reasoning and position. | C34: =OFFSET(Grading!K26, Grading!$AS$10,0) -> 0
B35: The writer has carefully marked references to other texts as such and clearly attributed ideas to others. It is always obvious who is "speaking" and whose positions--the writer's, those of others--are discussed in the artifact. | C35: =OFFSET(Grading!K27, Grading!$AS$10,0) -> 0
B36: References to other sources are formatted correctly and consistently; full bibliographic information is provided in the list of works cited. | C36: =OFFSET(Grading!K28, Grading!$AS$10,0) -> 0
B37: The writer has structured the content and organized paragraphs in line with readers' expectations. | C37: =OFFSET(Grading!K29, Grading!$AS$10,0) -> 0
B38: The texts are mostly correct in terms of spelling, punctuation, and grammar. | C38: =OFFSET(Grading!K30, Grading!$AS$10,0) -> 0

Sheet Stud9
A1: Instructor | B1: =Course!B3 -> 0
A2: Title | B2: =Course!B4 -> 0
A3: Course Number | B3: =Course!B5 -> 0
A5: Last Name | B5: =OFFSET(Grading!L7, Grading!$AS$10,0) -> 0
A6: First Name | B6: =OFFSET(Grading!L8, Grading!$AS$10,0) -> 0
A8: Grading Rubric
A9: max. total points per item: 5
A10: max. total points: 100
B11: 4–5 = criterion fully met
B12: 2–3 = criterion met for the most part
B13: 1 = criterion met to some extent
B14: 0 = criterion not met
B15: Total Score | C15: =OFFSET(Grading!L32, Grading!$AS$10,0) -> 0
A17: Artefact | B17: Items | C17: Points
A19: Research Question (Artefact 1a) | B19: The research question is precise and related to a specific topic. | C19: =OFFSET(Grading!L11, Grading!$AS$10,0) -> 0
A20: Reflections (Artefacts 1b, 2d, 3, and 4) | B20: The writer has carefully considered and deepy engaged with the topic. | C20: =OFFSET(Grading!L12, Grading!$AS$10,0) -> 0
B21: The writer has identified and described one specific situation. | C21: =OFFSET(Grading!L13, Grading!$AS$10,0) -> 0
B22: The writer has analyzed this specific situation. | C22: =OFFSET(Grading!L14, Grading!$AS$10,0) -> 0
B23: The writer relates different learning experiences, for example the current experience to an earlier one. | C23: =OFFSET(Grading!L15, Grading!$AS$10,0) -> 0
B24: The writer questions previously held assumptions, biases, or stereotypes. | C24: =OFFSET(Grading!L16, Grading!$AS$10,0) -> 0
B25: The writer has gained valuable new insignts. | C25: =OFFSET(Grading!L17, Grading!$AS$10,0) -> 0
B26: Based on these insights, the writer discusses implications for future actions, thinking, and learning. | C26: =OFFSET(Grading!L18, Grading!$AS$10,0) -> 0
A27: Response Paper (Artefact 2a-c) | B27: The writer identifies the main thesis and key arguments of the text. | C27: =OFFSET(Grading!L19, Grading!$AS$10,0) -> 0
B28: The writer elaborates on these main points and provides references to the text. | C28: =OFFSET(Grading!L20, Grading!$AS$10,0) -> 0
B29: The writer contextualizes these points by also drawing on high-quality sources. | C29: =OFFSET(Grading!L21, Grading!$AS$10,0) -> 0
B30: The writer considers relevant contextual information, for example historical context, audience, or intellectual tradition. | C30: =OFFSET(Grading!L22, Grading!$AS$10,0) -> 0
B31: The writer positions themselves vis-a-vis the text and, perhaps, in the debate to which the text contributes. | C31: =OFFSET(Grading!L23, Grading!$AS$10,0) -> 0
B32: The writer supports this position with reasonable arguments. | C32: =OFFSET(Grading!L24, Grading!$AS$10,0) -> 0
B33: The writer's diction, tone, and style is appropriate for an academic audience. | C33: =OFFSET(Grading!L25, Grading!$AS$10,0) -> 0
A34: Entire Portfolio | B34: It is easy to read the text and to understand the writer's reasoning and position. | C34: =OFFSET(Grading!L26, Grading!$AS$10,0) -> 0
B35: The writer has carefully marked references to other texts as such and clearly attributed ideas to others. It is always obvious who is "speaking" and whose positions--the writer's, those of others--are discussed in the artifact. | C35: =OFFSET(Grading!L27, Grading!$AS$10,0) -> 0
B36: References to other sources are formatted correctly and consistently; full bibliographic information is provided in the list of works cited. | C36: =OFFSET(Grading!L28, Grading!$AS$10,0) -> 0
B37: The writer has structured the content and organized paragraphs in line with readers' expectations. | C37: =OFFSET(Grading!L29, Grading!$AS$10,0) -> 0
B38: The texts are mostly correct in terms of spelling, punctuation, and grammar. | C38: =OFFSET(Grading!L30, Grading!$AS$10,0) -> 0

Sheet Stud10
A1: Instructor | B1: =Course!B3 -> 0
A2: Title | B2: =Course!B4 -> 0
A3: Course Number | B3: =Course!B5 -> 0
A5: Last Name | B5: =OFFSET(Grading!M7, Grading!$AS$10,0) -> 0
A6: First Name | B6: =OFFSET(Grading!M8, Grading!$AS$10,0) -> 0
A8: Grading Rubric
A9: max. total points per item: 5
A10: max. total points: 100
B11: 4–5 = criterion fully met
B12: 2–3 = criterion met for the most part
B13: 1 = criterion met to some extent
B14: 0 = criterion not met
B15: Total Score | C15: =OFFSET(Grading!M32, Grading!$AS$10,0) -> 0
A17: Artefact | B17: Items | C17: Points
A19: Research Question (Artefact 1a) | B19: The research question is precise and related to a specific topic. | C19: =OFFSET(Grading!M11, Grading!$AS$10,0) -> 0
A20: Reflections (Artefacts 1b, 2d, 3, and 4) | B20: The writer has carefully considered and deepy engaged with the topic. | C20: =OFFSET(Grading!M12, Grading!$AS$10,0) -> 0
B21: The writer has identified and described one specific situation. | C21: =OFFSET(Grading!M13, Grading!$AS$10,0) -> 0
B22: The writer has analyzed this specific situation. | C22: =OFFSET(Grading!M14, Grading!$AS$10,0) -> 0
B23: The writer relates different learning experiences, for example the current experience to an earlier one. | C23: =OFFSET(Grading!M15, Grading!$AS$10,0) -> 0
B24: The writer questions previously held assumptions, biases, or stereotypes. | C24: =OFFSET(Grading!M16, Grading!$AS$10,0) -> 0
B25: The writer has gained valuable new insignts. | C25: =OFFSET(Grading!M17, Grading!$AS$10,0) -> 0
B26: Based on these insights, the writer discusses implications for future actions, thinking, and learning. | C26: =OFFSET(Grading!M18, Grading!$AS$10,0) -> 0
A27: Response Paper (Artefact 2a-c) | B27: The writer identifies the main thesis and key arguments of the text. | C27: =OFFSET(Grading!M19, Grading!$AS$10,0) -> 0
B28: The writer elaborates on these main points and provides references to the text. | C28: =OFFSET(Grading!M20, Grading!$AS$10,0) -> 0
B29: The writer contextualizes these points by also drawing on high-quality sources. | C29: =OFFSET(Grading!M21, Grading!$AS$10,0) -> 0
B30: The writer considers relevant contextual information, for example historical context, audience, or intellectual tradition. | C30: =OFFSET(Grading!M22, Grading!$AS$10,0) -> 0
B31: The writer positions themselves vis-a-vis the text and, perhaps, in the debate to which the text contributes. | C31: =OFFSET(Grading!M23, Grading!$AS$10,0) -> 0
B32: The writer supports this position with reasonable arguments. | C32: =OFFSET(Grading!M24, Grading!$AS$10,0) -> 0
B33: The writer's diction, tone, and style is appropriate for an academic audience. | C33: =OFFSET(Grading!M25, Grading!$AS$10,0) -> 0
A34: Entire Portfolio | B34: It is easy to read the text and to understand the writer's reasoning and position. | C34: =OFFSET(Grading!M26, Grading!$AS$10,0) -> 0
B35: The writer has carefully marked references to other texts as such and clearly attributed ideas to others. It is always obvious who is "speaking" and whose positions--the writer's, those of others--are discussed in the artifact. | C35: =OFFSET(Grading!M27, Grading!$AS$10,0) -> 0
B36: References to other sources are formatted correctly and consistently; full bibliographic information is provided in the list of works cited. | C36: =OFFSET(Grading!M28, Grading!$AS$10,0) -> 0
B37: The writer has structured the content and organized paragraphs in line with readers' expectations. | C37: =OFFSET(Grading!M29, Grading!$AS$10,0) -> 0
B38: The texts are mostly correct in terms of spelling, punctuation, and grammar. | C38: =OFFSET(Grading!M30, Grading!$AS$10,0) -> 0

Sheet Stud11
A1: Instructor | B1: =Course!B3 -> 0
A2: Title | B2: =Course!B4 -> 0
A3: Course Number | B3: =Course!B5 -> 0
A5: Last Name | B5: =OFFSET(Grading!N7, Grading!$AS$10,0) -> 0
A6: First Name | B6: =OFFSET(Grading!N8, Grading!$AS$10,0) -> 0
A8: Grading Rubric
A9: max. total points per item: 5
A10: max. total points: 100
B11: 4–5 = criterion fully met
B12: 2–3 = criterion met for the most part
B13: 1 = criterion met to some extent
B14: 0 = criterion not met
B15: Total Score | C15: =OFFSET(Grading!N32, Grading!$AS$10,0) -> 0
A17: Artefact | B17: Items | C17: Points
A19: Research Question (Artefact 1a) | B19: The research question is precise and related to a specific topic. | C19: =OFFSET(Grading!N11, Grading!$AS$10,0) -> 0
A20: Reflections (Artefacts 1b, 2d, 3, and 4) | B20: The writer has carefully considered and deepy engaged with the topic. | C20: =OFFSET(Grading!N12, Grading!$AS$10,0) -> 0
B21: The writer has identified and described one specific situation. | C21: =OFFSET(Grading!N13, Grading!$AS$10,0) -> 0
B22: The writer has analyzed this specific situation. | C22: =OFFSET(Grading!N14, Grading!$AS$10,0) -> 0
B23: The writer relates different learning experiences, for example the current experience to an earlier one. | C23: =OFFSET(Grading!N15, Grading!$AS$10,0) -> 0
B24: The writer questions previously held assumptions, biases, or stereotypes. | C24: =OFFSET(Grading!N16, Grading!$AS$10,0) -> 0
B25: The writer has gained valuable new insignts. | C25: =OFFSET(Grading!N17, Grading!$AS$10,0) -> 0
B26: Based on these insights, the writer discusses implications for future actions, thinking, and learning. | C26: =OFFSET(Grading!N18, Grading!$AS$10,0) -> 0
A27: Response Paper (Artefact 2a-c) | B27: The writer identifies the main thesis and key arguments of the text. | C27: =OFFSET(Grading!N19, Grading!$AS$10,0) -> 0
B28: The writer elaborates on these main points and provides references to the text. | C28: =OFFSET(Grading!N20, Grading!$AS$10,0) -> 0
B29: The writer contextualizes these points by also drawing on high-quality sources. | C29: =OFFSET(Grading!N21, Grading!$AS$10,0) -> 0
B30: The writer considers relevant contextual information, for example historical context, audience, or intellectual tradition. | C30: =OFFSET(Grading!N22, Grading!$AS$10,0) -> 0
B31: The writer positions themselves vis-a-vis the text and, perhaps, in the debate to which the text contributes. | C31: =OFFSET(Grading!N23, Grading!$AS$10,0) -> 0
B32: The writer supports this position with reasonable arguments. | C32: =OFFSET(Grading!N24, Grading!$AS$10,0) -> 0
B33: The writer's diction, tone, and style is appropriate for an academic audience. | C33: =OFFSET(Grading!N25, Grading!$AS$10,0) -> 0
A34: Entire Portfolio | B34: It is easy to read the text and to understand the writer's reasoning and position. | C34: =OFFSET(Grading!N26, Grading!$AS$10,0) -> 0
B35: The writer has carefully marked references to other texts as such and clearly attributed ideas to others. It is always obvious who is "speaking" and whose positions--the writer's, those of others--are discussed in the artifact. | C35: =OFFSET(Grading!N27, Grading!$AS$10,0) -> 0
B36: References to other sources are formatted correctly and consistently; full bibliographic information is provided in the list of works cited. | C36: =OFFSET(Grading!N28, Grading!$AS$10,0) -> 0
B37: The writer has structured the content and organized paragraphs in line with readers' expectations. | C37: =OFFSET(Grading!N29, Grading!$AS$10,0) -> 0
B38: The texts are mostly correct in terms of spelling, punctuation, and grammar. | C38: =OFFSET(Grading!N30, Grading!$AS$10,0) -> 0

Sheet Stud12
A1: Instructor | B1: =Course!B3 -> 0
A2: Title | B2: =Course!B4 -> 0
A3: Course Number | B3: =Course!B5 -> 0
A5: Last Name | B5: =OFFSET(Grading!O7, Grading!$AS$10,0) -> 0
A6: First Name | B6: =OFFSET(Grading!O8, Grading!$AS$10,0) -> 0
A8: Grading Rubric
A9: max. total points per item: 5
A10: max. total points: 100
B11: 4–5 = criterion fully met
B12: 2–3 = criterion met for the most part
B13: 1 = criterion met to some extent
B14: 0 = criterion not met
B15: Total Score | C15: =OFFSET(Grading!O32, Grading!$AS$10,0) -> 0
A17: Artefact | B17: Items | C17: Points
A19: Research Question (Artefact 1a) | B19: The research question is precise and related to a specific topic. | C19: =OFFSET(Grading!O11, Grading!$AS$10,0) -> 0
A20: Reflections (Artefacts 1b, 2d, 3, and 4) | B20: The writer has carefully considered and deepy engaged with the topic. | C20: =OFFSET(Grading!O12, Grading!$AS$10,0) -> 0
B21: The writer has identified and described one specific situation. | C21: =OFFSET(Grading!O13, Grading!$AS$10,0) -> 0
B22: The writer has analyzed this specific situation. | C22: =OFFSET(Grading!O14, Grading!$AS$10,0) -> 0
B23: The writer relates different learning experiences, for example the current experience to an earlier one. | C23: =OFFSET(Grading!O15, Grading!$AS$10,0) -> 0
B24: The writer questions previously held assumptions, biases, or stereotypes. | C24: =OFFSET(Grading!O16, Grading!$AS$10,0) -> 0
B25: The writer has gained valuable new insignts. | C25: =OFFSET(Grading!O17, Grading!$AS$10,0) -> 0
B26: Based on these insights, the writer discusses implications for future actions, thinking, and learning. | C26: =OFFSET(Grading!O18, Grading!$AS$10,0) -> 0
A27: Response Paper (Artefact 2a-c) | B27: The writer identifies the main thesis and key arguments of the text. | C27: =OFFSET(Grading!O19, Grading!$AS$10,0) -> 0
B28: The writer elaborates on these main points and provides references to the text. | C28: =OFFSET(Grading!O20, Grading!$AS$10,0) -> 0
B29: The writer contextualizes these points by also drawing on high-quality sources. | C29: =OFFSET(Grading!O21, Grading!$AS$10,0) -> 0
B30: The writer considers relevant contextual information, for example historical context, audience, or intellectual tradition. | C30: =OFFSET(Grading!O22, Grading!$AS$10,0) -> 0
B31: The writer positions themselves vis-a-vis the text and, perhaps, in the debate to which the text contributes. | C31: =OFFSET(Grading!O23, Grading!$AS$10,0) -> 0
B32: The writer supports this position with reasonable arguments. | C32: =OFFSET(Grading!O24, Grading!$AS$10,0) -> 0
B33: The writer's diction, tone, and style is appropriate for an academic audience. | C33: =OFFSET(Grading!O25, Grading!$AS$10,0) -> 0
A34: Entire Portfolio | B34: It is easy to read the text and to understand the writer's reasoning and position. | C34: =OFFSET(Grading!O26, Grading!$AS$10,0) -> 0
B35: The writer has carefully marked references to other texts as such and clearly attributed ideas to others. It is always obvious who is "speaking" and whose positions--the writer's, those of others--are discussed in the artifact. | C35: =OFFSET(Grading!O27, Grading!$AS$10,0) -> 0
B36: References to other sources are formatted correctly and consistently; full bibliographic information is provided in the list of works cited. | C36: =OFFSET(Grading!O28, Grading!$AS$10,0) -> 0
B37: The writer has structured the content and organized paragraphs in line with readers' expectations. | C37: =OFFSET(Grading!O29, Grading!$AS$10,0) -> 0
B38: The texts are mostly correct in terms of spelling, punctuation, and grammar. | C38: =OFFSET(Grading!O30, Grading!$AS$10,0) -> 0

Sheet Stud13
A1: Instructor | B1: =Course!B3 -> 0
A2: Title | B2: =Course!B4 -> 0
A3: Course Number | B3: =Course!B5 -> 0
A5: Last Name | B5: =OFFSET(Grading!P7, Grading!$AS$10,0) -> 0
A6: First Name | B6: =OFFSET(Grading!P8, Grading!$AS$10,0) -> 0
A8: Grading Rubric
A9: max. total points per item: 5
A10: max. total points: 100
B11: 4–5 = criterion fully met
B12: 2–3 = criterion met for the most part
B13: 1 = criterion met to some extent
B14: 0 = criterion not met
B15: Total Score | C15: =OFFSET(Grading!P32, Grading!$AS$10,0) -> 0
A17: Artefact | B17: Items | C17: Points
A19: Research Question (Artefact 1a) | B19: The research question is precise and related to a specific topic. | C19: =OFFSET(Grading!P11, Grading!$AS$10,0) -> 0
A20: Reflections (Artefacts 1b, 2d, 3, and 4) | B20: The writer has carefully considered and deepy engaged with the topic. | C20: =OFFSET(Grading!P12, Grading!$AS$10,0) -> 0
B21: The writer has identified and described one specific situation. | C21: =OFFSET(Grading!P13, Grading!$AS$10,0) -> 0
B22: The writer has analyzed this specific situation. | C22: =OFFSET(Grading!P14, Grading!$AS$10,0) -> 0
B23: The writer relates different learning experiences, for example the current experience to an earlier one. | C23: =OFFSET(Grading!P15, Grading!$AS$10,0) -> 0
B24: The writer questions previously held assumptions, biases, or stereotypes. | C24: =OFFSET(Grading!P16, Grading!$AS$10,0) -> 0
B25: The writer has gained valuable new insignts. | C25: =OFFSET(Grading!P17, Grading!$AS$10,0) -> 0
B26: Based on these insights, the writer discusses implications for future actions, thinking, and learning. | C26: =OFFSET(Grading!P18, Grading!$AS$10,0) -> 0
A27: Response Paper (Artefact 2a-c) | B27: The writer identifies the main thesis and key arguments of the text. | C27: =OFFSET(Grading!P19, Grading!$AS$10,0) -> 0
B28: The writer elaborates on these main points and provides references to the text. | C28: =OFFSET(Grading!P20, Grading!$AS$10,0) -> 0
B29: The writer contextualizes these points by also drawing on high-quality sources. | C29: =OFFSET(Grading!P21, Grading!$AS$10,0) -> 0
B30: The writer considers relevant contextual information, for example historical context, audience, or intellectual tradition. | C30: =OFFSET(Grading!P22, Grading!$AS$10,0) -> 0
B31: The writer positions themselves vis-a-vis the text and, perhaps, in the debate to which the text contributes. | C31: =OFFSET(Grading!P23, Grading!$AS$10,0) -> 0
B32: The writer supports this position with reasonable arguments. | C32: =OFFSET(Grading!P24, Grading!$AS$10,0) -> 0
B33: The writer's diction, tone, and style is appropriate for an academic audience. | C33: =OFFSET(Grading!P25, Grading!$AS$10,0) -> 0
A34: Entire Portfolio | B34: It is easy to read the text and to understand the writer's reasoning and position. | C34: =OFFSET(Grading!P26, Grading!$AS$10,0) -> 0
B35: The writer has carefully marked references to other texts as such and clearly attributed ideas to others. It is always obvious who is "speaking" and whose positions--the writer's, those of others--are discussed in the artifact. | C35: =OFFSET(Grading!P27, Grading!$AS$10,0) -> 0
B36: References to other sources are formatted correctly and consistently; full bibliographic information is provided in the list of works cited. | C36: =OFFSET(Grading!P28, Grading!$AS$10,0) -> 0
B37: The writer has structured the content and organized paragraphs in line with readers' expectations. | C37: =OFFSET(Grading!P29, Grading!$AS$10,0) -> 0
B38: The texts are mostly correct in terms of spelling, punctuation, and grammar. | C38: =OFFSET(Grading!P30, Grading!$AS$10,0) -> 0

Sheet Stud14
A1: Instructor | B1: =Course!B3 -> 0
A2: Title | B2: =Course!B4 -> 0
A3: Course Number | B3: =Course!B5 -> 0
A5: Last Name | B5: =OFFSET(Grading!Q7, Grading!$AS$10,0) -> 0
A6: First Name | B6: =OFFSET(Grading!Q8, Grading!$AS$10,0) -> 0
A8: Grading Rubric
A9: max. total points per item: 5
A10: max. total points: 100
B11: 4–5 = criterion fully met
B12: 2–3 = criterion met for the most part
B13: 1 = criterion met to some extent
B14: 0 = criterion not met
B15: Total Score | C15: =OFFSET(Grading!Q32, Grading!$AS$10,0) -> 0
A17: Artefact | B17: Items | C17: Points
A19: Research Question (Artefact 1a) | B19: The research question is precise and related to a specific topic. | C19: =OFFSET(Grading!Q11, Grading!$AS$10,0) -> 0
A20: Reflections (Artefacts 1b, 2d, 3, and 4) | B20: The writer has carefully considered and deepy engaged with the topic. | C20: =OFFSET(Grading!Q12, Grading!$AS$10,0) -> 0
B21: The writer has identified and described one specific situation. | C21: =OFFSET(Grading!Q13, Grading!$AS$10,0) -> 0
B22: The writer has analyzed this specific situation. | C22: =OFFSET(Grading!Q14, Grading!$AS$10,0) -> 0
B23: The writer relates different learning experiences, for example the current experience to an earlier one. | C23: =OFFSET(Grading!Q15, Grading!$AS$10,0) -> 0
B24: The writer questions previously held assumptions, biases, or stereotypes. | C24: =OFFSET(Grading!Q16, Grading!$AS$10,0) -> 0
B25: The writer has gained valuable new insignts. | C25: =OFFSET(Grading!Q17, Grading!$AS$10,0) -> 0
B26: Based on these insights, the writer discusses implications for future actions, thinking, and learning. | C26: =OFFSET(Grading!Q18, Grading!$AS$10,0) -> 0
A27: Response Paper (Artefact 2a-c) | B27: The writer identifies the main thesis and key arguments of the text. | C27: =OFFSET(Grading!Q19, Grading!$AS$10,0) -> 0
B28: The writer elaborates on these main points and provides references to the text. | C28: =OFFSET(Grading!Q20, Grading!$AS$10,0) -> 0
B29: The writer contextualizes these points by also drawing on high-quality sources. | C29: =OFFSET(Grading!Q21, Grading!$AS$10,0) -> 0
B30: The writer considers relevant contextual information, for example historical context, audience, or intellectual tradition. | C30: =OFFSET(Grading!Q22, Grading!$AS$10,0) -> 0
B31: The writer positions themselves vis-a-vis the text and, perhaps, in the debate to which the text contributes. | C31: =OFFSET(Grading!Q23, Grading!$AS$10,0) -> 0
B32: The writer supports this position with reasonable arguments. | C32: =OFFSET(Grading!Q24, Grading!$AS$10,0) -> 0
B33: The writer's diction, tone, and style is appropriate for an academic audience. | C33: =OFFSET(Grading!Q25, Grading!$AS$10,0) -> 0
A34: Entire Portfolio | B34: It is easy to read the text and to understand the writer's reasoning and position. | C34: =OFFSET(Grading!Q26, Grading!$AS$10,0) -> 0
